Workbook

Sheet Cover
B2: SITC International Holdings Co Ltd (1308.HK)
B3: Financial model - initiating coverage, 25 October 2026
B5: Key outputs (active scenario)
B6: Active scenario | C6: =Scenarios!D3 -> Base
B7: Share price (HK$) | C7: =Inputs!C6 -> 47.68
B8: Market cap (US$m) | C8: =Inputs!C16 -> 16487.785
B9: FY2026E diluted EPS (HK$) | C9: ='Income Statement'!H59 -> 4.2666165
B10: FY2027E diluted EPS (HK$) | C10: ='Income Statement'!I59 -> 3.4208878
B11: FY2026E P/E (x) | C11: =Inputs!C6/'Income Statement'!H59 -> 11.175131
B12: FY2027E P/E (x) | C12: =Inputs!C6/'Income Statement'!I59 -> 13.937902
B13: FY2026E DPS (HK$) | C13: ='Income Statement'!H60 -> 3.6192301
B14: FY2026E dividend yield | C14: ='Income Statement'!H60/Inputs!C6 -> 0.075906672
B15: Net cash excl. leases, YE2026E (US$m) | C15: ='Balance Sheet'!H53 -> 917.24481
B16: DCF value per share (HK$) | C16: =DCF!C53 -> 36.221802
B17: 12-month price target (HK$) | C17: ='Valuation Summary'!C20 -> 36.5
B18: Expected 12-month total return | C18: ='Valuation Summary'!C24 -> -0.15843555
B19: Rating | C19: ='Valuation Summary'!C25 -> SELL
B20: All checks pass | C20: =Checks!C47 -> TRUE
B22: Tabs
B23: Inputs | D23: Share price, FX, share count, declared dividends and opening balances.
B24: Scenarios | D24: Bull / Base / Bear drivers with selector (C3), common assumptions, and the stored scenario output table.
B25: Interim | D25: 1H25A, 2H25A, 1H26A, 2H26E, 9M and quarterly bridge; FY2026E volume and rate are 9M26 actuals plus a Q4 estimate.
B26: Revenue Model | D26: Fleet capacity, volume, freight rate and revenue streams (27 rows); revenue by geography (16 rows).
B27: Income Statement | D27: FY2021A-FY2030E, cost of sales by line, unit costs, EBIT/EBITDA, segment result, EPS and DPS.
B28: Cash Flow | D28: Indirect method; capex and newbuild instalments, dividends (declared vs paid), revolver and free cash flow.
B29: Balance Sheet | D29: Full statement of financial position; PPE, ROU, advances and lease roll-forwards; net cash; ROE.
B30: DCF Inputs | D30: Unlevered free cash flow after leases; bridge items; cycle reference per TEU.
B31: DCF | D31: WACC build, FY2027E-30E UFCF, Gordon terminal value, equity bridge and reverse DCF.
B32: Sensitivity | D32: WACC x g and revenue CAGR x EBITDA margin DCF grids; P/E x scenario EPS; FY2027E freight-rate sensitivity.
B33: Comps | D33: 12 listed container lines with statistical summary (max / 75th / median / 25th / min) and implied values.
B34: Valuation Summary | D34: Weighted price target, rating rule, cross-checks (DDM, justified P/B, scenarios) and probability weighting.
B35: Checks | D35: Balance, cash, tie-out of every historical total to the filings, scenario-store consistency.
B38: Conventions
B39: Blue | D39: Hard-coded input (reported historical figures and forecast assumptions)
B40: Black | D40: Formula
B41: Green | D41: Direct link to another tab
B42: Shaded columns | D42: Forecast periods (FY2026E-FY2030E; 2H26E and Q4 26E on Interim)
B44: Sources
B45: SITC annual reports 2022, 2023 and 2025; annual results announcements FY2018-FY2025; 2026 Interim Report (HKEX).
B46: Operating statistics for the nine months to 30-Sep-2026 and special dividend announcement (22-Oct-2026).
...

Sheet Inputs
A1: SITC International Holdings (1308.HK) - Inputs
A2: Market data and fixed inputs. Blue = input; black = formula; green = link to another tab.
A4: Item | B4: Unit | C4: Value | D4: Source / note
A5: Market data
A6: Share price (last close, 23-Oct-2026) | B6: HK$ | C6: 47.68 | D6: Yahoo Finance chart API, 1308.HK, close 23-Oct-2026
A7: HK$ per US$ | B7: HK$/US$ | C7: 7.8413 | D7: Yahoo Finance HKD=X, 23-Oct-2026
A8: 52-week high | B8: HK$ | C8: 52 | D8: Yahoo Finance, 1-year range
A9: 52-week low | B9: HK$ | C9: 26.22 | D9: Yahoo Finance, 1-year range
A10: Valuation date | B10: date | C10: 46320 | D10: Report date
A11: Share count
A12: Ordinary shares in issue | B12: m | C12: 2711.5282 | D12: HKEX monthly return for September 2026 (2,711,528,233 shares); includes ~34m held by the share-scheme trustee
A13: Dilution from outstanding share options | B13: m | C13: 0 | D13: 2026 Interim Report note 9: share options had no dilutive effect in 1H26
A14: Shares used for per-share value | B14: m | C14: =$C$12+$C$13 -> 2711.5282 | D14: Trustee-held scheme shares are deemed dilutive, so shares in issue is the diluted count
A15: Market capitalisation | B15: HK$m | C15: =$C$6*$C$14 -> 129285.67
A16: Market capitalisation | B16: US$m | C16: =$C$15/$C$7 -> 16487.785
A17: Dividends already declared
A18: FY2026 interim dividend (paid Sep-2026) | B18: HK$/sh | C18: 1.5 | D18: 2026 interim results announcement, 19-Aug-2026
A19: FY2026 special dividend (ex 4-Dec-2026, paid 17-Dec-2026) | B19: HK$/sh | C19: 1 | D19: Announcement 22-Oct-2026
A20: FY2026 dividends paid within 2026 | B20: HK$/sh | C20: =$C$18+$C$19 -> 2.5
A21: FY2025 final dividend paid in 2026 (cash) | B21: US$m | C21: 344.572 | D21: 1H26 dividends paid US$587.4m less the 2025 special payable of US$242.8m at 31-Dec-2025
A22: Opening balances for FY2021 growth rates
A23: Fleet capacity, 31-Dec-2020 | B23: TEU '000 | C23: 129.652 | D23: 2020 annual results announcement
A24: Container shipping volume, FY2020 | B24: TEU '000 | C24: 2614.203 | D24: 2020 annual results announcement
A25: Average freight rate excl. slot exchange, FY2020 | B25: US$/TEU | C25: 545.1 | D25: 2020 annual results announcement
A26: Cash and cash equivalents, 31-Dec-2020 | B26: US$m | C26: 61.139 | D26: 2022 Annual Report, consolidated statement of cash flows (2021 comparative)
A27: Financing policy
A28: Minimum cash and cash equivalents (revolver trigger) | B28: US$m | C28: 150 | D28: Our assumption; time deposits and FVTPL assets are set separately on Scenarios

Sheet Scenarios
A1: SITC International Holdings (1308.HK) - Scenarios
A2: Forecast drivers. Change C3 to switch the whole model between Bull (1), Base (2) and Bear (3).
A3: Active scenario (1 = Bull, 2 = Base, 3 = Bear) | C3: 2 | D3: =CHOOSE($C$3,"Bull","Base","Bear") -> Base
A4: Driver | B4: Unit | C4: FY2021A | D4: FY2022A | E4: FY2023A | F4: FY2024A | G4: FY2025A | H4: FY2026E | I4: FY2027E | J4: FY2028E | K4: FY2029E | L4: FY2030E | M4: Rationale / evidence
A5: Scenario drivers (Bull / Base / Bear; the Selected row feeds the model)
A6: Q4 2026 volume growth, year on year | B6: % | M6: 9M26 +5.9% YoY; Q4 2025 was a strong base (1.10m TEU)
A7: Bull | H7: 0.06
A8: Base | H8: 0.04
A9: Bear | H9: 0.01
A10: Selected | H10: =CHOOSE($C$3,H7,H8,H9) -> 0.04
A11: Q4 2026 average freight rate | B11: US$/TEU | M11: Q3 2026 implied US$865/TEU (Interim tab); Hormuz-related fuel and freight premium fading since July
A12: Bull | H12: 870
A13: Base | H13: 845
A14: Bear | H14: 810
A15: Selected | H15: =CHOOSE($C$3,H12,H13,H14) -> 845
A16: Container volume growth | B16: % | M16: FY2017-25 CAGR 6.3%; newbuild deliveries raise capacity ~10% a year in 2027-28
A17: Bull | I17: 0.07 | J17: 0.06 | K17: 0.05 | L17: 0.04
A18: Base | I18: 0.05 | J18: 0.05 | K18: 0.04 | L18: 0.035
A19: Bear | I19: 0.02 | J19: 0.03 | K19: 0.03 | L19: 0.03
A20: Selected | I20: =CHOOSE($C$3,I17,I18,I19) -> 0.05 | J20: =CHOOSE($C$3,J17,J18,J19) -> 0.05 | K20: =CHOOSE($C$3,K17,K18,K19) -> 0.04 | L20: =CHOOSE($C$3,L17,L18,L19) -> 0.035
A21: Average freight rate change | B21: % | M21: Base returns the rate to about the 2024-25 level by 2028; bear revisits the 2023 trough (US$623)
A22: Bull | I22: -0.03 | J22: 0 | K22: 0.01 | L22: 0.02
A23: Base | I23: -0.1 | J23: -0.05 | K23: 0 | L23: 0.01
A24: Bear | I24: -0.2 | J24: -0.08 | K24: 0 | L24: 0.02
A25: Selected | I25: =CHOOSE($C$3,I22,I23,I24) -> -0.1 | J25: =CHOOSE($C$3,J22,J23,J24) -> -0.05 | K25: =CHOOSE($C$3,K22,K23,K24) -> 0 | L25: =CHOOSE($C$3,L22,L23,L24) -> 0.01
A26: Vessel cost per average TEU slot, change | B26: % | M26: Charter-hire relief as global deliveries land; owned newbuilds carry depreciation instead
A27: Bull | I27: -0.03 | J27: -0.02 | K27: 0 | L27: 0.01
A28: Base | I28: -0.02 | J28: -0.01 | K28: 0.01 | L28: 0.015
A29: Bear | I29: 0 | J29: 0 | K29: 0.01 | L29: 0.02
A30: Selected | I30: =CHOOSE($C$3,I27,I28,I29) -> -0.02 | J30: =CHOOSE($C$3,J27,J28,J29) -> -0.01 | K30: =CHOOSE($C$3,K27,K28,K29) -> 0.01 | L30: =CHOOSE($C$3,L27,L28,L29) -> 0.015
A31: Other container logistics income growth | B31: % | M31: 1H26 +28.5% YoY
A32: Bull | H32: 0.25 | I32: 0.1 | J32: 0.08 | K32: 0.07 | L32: 0.06
A33: Base | H33: 0.22 | I33: 0.06 | J33: 0.05 | K33: 0.05 | L33: 0.04
A34: Bear | H34: 0.2 | I34: 0 | J34: 0.02 | K34: 0.03 | L34: 0.03
A35: Selected | H35: =CHOOSE($C$3,H32,H33,H34) -> 0.22 | I35: =CHOOSE($C$3,I32,I33,I34) -> 0.06 | J35: =CHOOSE($C$3,J32,J33,J34) -> 0.05 | K35: =CHOOSE($C$3,K32,K33,K34) -> 0.05 | L35: =CHOOSE($C$3,L32,L33,L34) -> 0.04
A36: Dividend payout (declared / attributable profit) | B36: % | M36: FY2021-25 payout 70-93% of EPS incl. specials; policy allows up to 100%
A37: Bull | H37: 0.9 | I37: 0.9 | J37: 0.9 | K37: 0.9 | L37: 0.9
A38: Base | H38: 0.85 | I38: 0.8 | J38: 0.8 | K38: 0.8 | L38: 0.8
A39: Bear | H39: 0.8 | I39: 0.7 | J39: 0.7 | K39: 0.7 | L39: 0.7
A40: Selected | H40: =CHOOSE($C$3,H37,H38,H39) -> 0.85 | I40: =CHOOSE($C$3,I37,I38,I39) -> 0.8 | J40: =CHOOSE($C$3,J37,J38,J39) -> 0.8 | K40: =CHOOSE($C$3,K37,K38,K39) -> 0.8 | L40: =CHOOSE($C$3,L37,L38,L39) -> 0.8
...

Sheet Interim
A1: SITC International Holdings (1308.HK) - Interim
A2: Half-year and quarterly bridge. 1H and 9M actuals from HKEX filings; 2H and Q4 derived; FY2026E links to the annual model.
A4: US$m unless stated | B4: Unit | C4: 1H25A | D4: 2H25A | E4: FY2025A | F4: 1H26A | G4: 2H26E | H4: FY2026E | I4: 9M25A | J4: 9M26A | K4: Q4 25A | L4: Q4 26E | M4: Q3 25A | N4: Q3 26A | O4: Note
A5: Operating statistics
A6: Container shipping volume | B6: TEU '000 | C6: 1829.665 | D6: =E6-C6 -> 2017.874 | E6: ='Revenue Model'!G12 -> 3847.539 | F6: 1971.942 | G6: =H6-F6 -> 2081.7778 | H6: =J6+L6 -> 4053.7198 | I6: 2749.844 | J6: 2912.117 | K6: =E6-I6 -> 1097.695 | L6: =K6*(1+Scenarios!H10) -> 1141.6028 | M6: =I6-C6 -> 920.179 | N6: =J6-F6 -> 940.175 | O6: Interim reports; 9M operating statistics announcements (22-Oct-2026)
A7: Volume growth, year on year | B7: % | F7: =F6/C6-1 -> 0.07776123 | G7: =G6/D6-1 -> 0.031668875 | H7: =H6/E6-1 -> 0.053587709 | J7: =J6/I6-1 -> 0.059011711 | L7: =L6/K6-1 -> 0.04 | N7: =N6/M6-1 -> 0.021730555
A8: Average freight rate (excl. slot exchange) | B8: US$/TEU | C8: 776.4 | D8: =(E8*E6-C8*C6)/D6 -> 732.35456 | E8: ='Revenue Model'!G15 -> 753.3 | F8: 807.2 | G8: =(H8*H6-F8*F6)/G6 -> 854.08741 | H8: =(J8*J6+L8*L6)/H6 -> 831.27891 | I8: 754.9 | J8: 825.9 | K8: =(E8*E6-I8*I6)/K6 -> 749.29183 | L8: =Scenarios!H15 -> 845 | M8: =(I8*I6-C8*C6)/M6 -> 712.14984 | N8: =(J8*J6-F8*F6)/N6 -> 865.12176 | O8: Q4 and Q3 rates derived from cumulative period averages
A9: Freight rate change, year on year | B9: % | F9: =F8/C8-1 -> 0.039670273 | G9: =G8/D8-1 -> 0.1662212 | H9: =H8/E8-1 -> 0.10351641 | J9: =J8/I8-1 -> 0.094052192 | L9: =L8/K8-1 -> 0.1277315 | N9: =N8/M8-1 -> 0.21480299
A10: Revenue | B10: US$m | C10: =C18 -> 1664.489 | D10: =D18 -> 1747.158 | E10: =E18 -> 3411.647 | F10: =F18 -> 1842.065 | G10: =G18 -> 2052.2664 | H10: =H18 -> 3894.3314 | I10: 2458.9 | J10: 2808.1 | K10: =E10-I10 -> 952.747 | L10: =H10-J10 -> 1086.2314 | M10: =I10-C10 -> 794.411 | N10: =J10-F10 -> 966.035 | O10: 9M figures are rounded to US$0.1m in the announcements
A11: Revenue growth, year on year | B11: % | F11: =F10/C10-1 -> 0.10668499 | G11: =G10/D10-1 -> 0.17463129 | H11: =H10/E10-1 -> 0.14148136 | J11: =J10/I10-1 -> 0.14201472 | L11: =L10/K10-1 -> 0.14010482 | N11: =N10/M10-1 -> 0.2160393
A12: Revenue per TEU lifted | B12: US$/TEU | C12: =C10/C6*1000 -> 909.72336 | D12: =D10/D6*1000 -> 865.84098 | E12: =E10/E6*1000 -> 886.70888 | F12: =F10/F6*1000 -> 934.13752 | G12: =G10/G6*1000 -> 985.82397 | H12: =H10/H6*1000 -> 960.68096 | I12: =I10/I6*1000 -> 894.19618 | J12: =J10/J6*1000 -> 964.28131 | ... N12: =N10/N6*1000 -> 1027.5055
A14: Half-year income statement
A15: Container shipping and supporting logistics income | B15: US$m | C15: 1512.689 | D15: =E15-C15 -> 1565.129 | E15: ='Income Statement'!G6 -> 3077.818 | F15: 1646.812 | G15: =H15-F15 -> 1840.9018 | H15: ='Income Statement'!H6 -> 3487.7138
A16: Other container logistics income | B16: US$m | C16: 150.696 | D16: =E16-C16 -> 180.466 | E16: ='Income Statement'!G7 -> 331.162 | F16: 193.678 | G16: =H16-F16 -> 210.33964 | H16: ='Income Statement'!H7 -> 404.01764
A17: Other sources | B17: US$m | C17: 1.104 | D17: =E17-C17 -> 1.563 | E17: ='Income Statement'!G8 -> 2.667 | F17: 1.575 | G17: =H17-F17 -> 1.025 | H17: ='Income Statement'!H8 -> 2.6
A18: Total revenue | B18: US$m | C18: =C15+C16+C17 -> 1664.489 | D18: =D15+D16+D17 -> 1747.158 | E18: =E15+E16+E17 -> 3411.647 | F18: =F15+F16+F17 -> 1842.065 | G18: =G15+G16+G17 -> 2052.2664 | H18: =H15+H16+H17 -> 3894.3314
A19: Equipment and cargo transportation costs | B19: US$m | C19: -520.451 | D19: =E19-C19 -> -572.715 | E19: ='Income Statement'!G12 -> -1093.166 | F19: -539.361 | G19: =H19-F19 -> -579.46566 | H19: ='Income Statement'!H12 -> -1118.8267
A20: Voyage costs | B20: US$m | C20: -198.651 | D20: =E20-C20 -> -203.795 | E20: ='Income Statement'!G13 -> -402.446 | F20: -226.702 | G20: =H20-F20 -> -241.50264 | H20: ='Income Statement'!H13 -> -468.20464
A21: Container shipping vessel costs | B21: US$m | C21: -151.911 | D21: =E21-C21 -> -177.515 | E21: ='Income Statement'!G14 -> -329.426 | F21: -180.231 | G21: =H21-F21 -> -184.54656 | H21: ='Income Statement'!H14 -> -364.77756
A22: Other container logistics costs | B22: US$m | C22: -123.697 | D22: =E22-C22 -> -150.831 | E22: ='Income Statement'!G15 -> -274.528 | F22: -161.511 | G22: =H22-F22 -> -173.82364 | H22: ='Income Statement'!H15 -> -335.33464
A23: Other costs | B23: US$m | C23: -0.348 | D23: =E23-C23 -> -1.267 | E23: ='Income Statement'!G16 -> -1.615 | F23: -1.027 | G23: =H23-F23 -> -0.533 | H23: ='Income Statement'!H16 -> -1.56
A24: Total cost of sales | B24: US$m | C24: =SUM(C19:C23) -> -995.058 | D24: =SUM(D19:D23) -> -1106.123 | E24: =SUM(E19:E23) -> -2101.181 | F24: =SUM(F19:F23) -> -1108.832 | G24: =SUM(G19:G23) -> -1179.8715 | H24: =SUM(H19:H23) -> -2288.7035
A25: Gross profit | B25: US$m | C25: =C18+C24 -> 669.431 | D25: =D18+D24 -> 641.035 | E25: =E18+E24 -> 1310.466 | F25: =F18+F24 -> 733.233 | G25: =G18+G24 -> 872.39495 | H25: =H18+H24 -> 1605.6279
A26: Gross margin | B26: % | C26: =C25/C18 -> 0.40218409 | D26: =D25/D18 -> 0.36690156 | E26: =E25/E18 -> 0.38411536 | F26: =F25/F18 -> 0.39804947 | G26: =G25/G18 -> 0.42508854 | H26: =H25/H18 -> 0.41229874
A27: Other income and gains (excl. interest) | B27: US$m | C27: 18.04 | D27: =E27-C27 -> 26.987 | E27: ='Income Statement'!G29+'Income Statement'!G30 -> 45.027 | F27: 13.511 | G27: =H27-F27 -> 8.489 | H27: ='Income Statement'!H29+'Income Statement'!H30 -> 22 | O27: 1H26 incl. US$6.2m vessel disposal gain (1H25 US$13.8m)
A28: Administrative expenses | B28: US$m | C28: -67.809 | D28: =E28-C28 -> -85.769 | E28: ='Income Statement'!G31 -> -153.578 | F28: -79.445 | G28: =H28-F28 -> -94.09814 | H28: ='Income Statement'!H31 -> -173.54314
A29: Other expenses, net | B29: US$m | C29: -1.673 | D29: =E29-C29 -> -4.013 | E29: ='Income Statement'!G33 -> -5.686 | F29: -1.804 | G29: =H29-F29 -> -2.196 | H29: ='Income Statement'!H33 -> -4
A30: Share of JV profits | B30: US$m | C30: 13.348 | D30: =E30-C30 -> 17.732 | E30: ='Income Statement'!G41 -> 31.08 | F30: 16.81 | G30: =H30-F30 -> 19.2428 | H30: ='Income Statement'!H41 -> 36.0528
A31: Share of associates | B31: US$m | C31: 0.954 | D31: =E31-C31 -> 0.725 | E31: ='Income Statement'!G42 -> 1.679 | F31: 0.525 | G31: =H31-F31 -> 0.975 | H31: ='Income Statement'!H42 -> 1.5
A32: Segment results | B32: US$m | C32: =C25+C27+C28+C29+C30+C31 -> 632.291 | D32: =D25+D27+D28+D29+D30+D31 -> 596.697 | E32: =E25+E27+E28+E29+E30+E31 -> 1228.988 | F32: =F25+F27+F28+F29+F30+F31 -> 682.83 | G32: =G25+G27+G28+G29+G30+G31 -> 804.80761 | H32: =H25+H27+H28+H29+H30+H31 -> 1487.6376
A33: Finance costs | B33: US$m | C33: -8.466 | D33: =E33-C33 -> -7.084 | E33: ='Income Statement'!G45 -> -15.55 | F33: -6.995 | G33: =H33-F33 -> -6.947578 | H33: ='Income Statement'!H45 -> -13.942578
A34: Bank interest income and FV gains | B34: US$m | C34: 19.782 | D34: =E34-C34 -> 18.049 | E34: ='Income Statement'!G44 -> 37.831 | F34: 16.569 | G34: =H34-F34 -> 16.63249 | H34: ='Income Statement'!H44 -> 33.20149
A35: Profit before tax | B35: US$m | C35: =C32+C33+C34 -> 643.607 | D35: =D32+D33+D34 -> 607.662 | E35: =E32+E33+E34 -> 1251.269 | F35: =F32+F33+F34 -> 692.404 | G35: =G32+G33+G34 -> 814.49252 | H35: =H32+H33+H34 -> 1506.8965
A36: Income tax | B36: US$m | C36: -10.159 | D36: =E36-C36 -> -10.708 | E36: ='Income Statement'!G47 -> -20.867 | F36: -11.935 | G36: =H36-F36 -> -13.682241 | H36: ='Income Statement'!H47 -> -25.617241
A37: Profit for the period | B37: US$m | C37: =C35+C36 -> 633.448 | D37: =D35+D36 -> 596.954 | E37: =E35+E36 -> 1230.402 | F37: =F35+F36 -> 680.469 | G37: =G35+G36 -> 800.81028 | H37: =H35+H36 -> 1481.2793
A38: Non-controlling interests | B38: US$m | C38: -3.453 | D38: =E38-C38 -> -4.062 | E38: ='Income Statement'!G51 -> -7.515 | F38: -3.928 | G38: =H38-F38 -> -4.9596757 | H38: ='Income Statement'!H51 -> -8.8876757
A39: Profit attributable to shareholders | B39: US$m | C39: =C37+C38 -> 629.995 | D39: =D37+D38 -> 592.892 | E39: =E37+E38 -> 1222.887 | F39: =F37+F38 -> 676.541 | G39: =G37+G38 -> 795.8506 | H39: =H37+H38 -> 1472.3916
A40: Depreciation of PPE (memo) | B40: US$m | C40: 57.211 | D40: =E40-C40 -> 58.803 | E40: ='Income Statement'!G36 -> 116.014 | F40: 57.516 | G40: =H40-F40 -> 57.25904 | H40: ='Income Statement'!H36 -> 114.77504
A41: Depreciation of ROU assets (memo) | B41: US$m | C41: 27.523 | D41: =E41-C41 -> 36.708 | E41: ='Income Statement'!G37 -> 64.231 | F41: 33.656 | G41: =H41-F41 -> 34.83424 | H41: ='Income Statement'!H37 -> 68.49024
A43: Half-year unit economics
...

Sheet Revenue Model
A1: SITC International Holdings (1308.HK) - Revenue Model
A2: Fleet, volume and freight-rate drivers; revenue by stream and by geography. US$m unless stated.
A4: US$m unless stated | B4: Unit | C4: FY2021A | D4: FY2022A | E4: FY2023A | F4: FY2024A | G4: FY2025A | H4: FY2026E | I4: FY2027E | J4: FY2028E | K4: FY2029E | L4: FY2030E | M4: Source / assumption
A5: A. Fleet, volume and freight rate
A6: Fleet capacity, start of year | B6: TEU '000 | C6: =Inputs!$C$23 -> 129.652 | D6: =C9 -> 143.115 | E6: =D9 -> 162.701 | F6: =E9 -> 162.851 | G6: =F9 -> 180.255 | H6: =G9 -> 184.961 | I6: =H9 -> 187.261 | J6: =I9 -> 201.261 | K6: =J9 -> 216.261 | L6: =K9 -> 216.461
A7: Newbuild deliveries | B7: TEU '000 | H7: =Scenarios!H44 -> 4 | I7: =Scenarios!I44 -> 26 | J7: =Scenarios!J44 -> 30 | K7: =Scenarios!K44 -> 6.2 | L7: =Scenarios!L44 -> 0
A8: Disposals and charter redeliveries | B8: TEU '000 | H8: =Scenarios!H45 -> 1.7 | I8: =Scenarios!I45 -> 12 | J8: =Scenarios!J45 -> 15 | K8: =Scenarios!K45 -> 6 | L8: =Scenarios!L45 -> 4
A9: Fleet capacity, year end | B9: TEU '000 | C9: 143.115 | D9: 162.701 | E9: 162.851 | F9: 180.255 | G9: 184.961 | H9: =H6+H7-H8 -> 187.261 | I9: =I6+I7-I8 -> 201.261 | J9: =J6+J7-J8 -> 216.261 | K9: =K6+K7-K8 -> 216.461 | L9: =L6+L7-L8 -> 212.461 | M9: Annual reports (operated fleet incl. chartered); 2025: 119 vessels
A10: Fleet capacity growth | B10: % | C10: =C9/C6-1 -> 0.10383951 | D10: =D9/D6-1 -> 0.13685498 | E10: =E9/E6-1 -> 0.00092193656 | F10: =F9/F6-1 -> 0.1068707 | G10: =G9/G6-1 -> 0.026107459 | H10: =H9/H6-1 -> 0.012435054 | I10: =I9/I6-1 -> 0.074761963 | J10: =J9/J6-1 -> 0.074530088 | ... L10: =L9/L6-1 -> -0.018479079
A11: Average fleet capacity | B11: TEU '000 | C11: =AVERAGE(C6,C9) -> 136.3835 | D11: =AVERAGE(D6,D9) -> 152.908 | E11: =AVERAGE(E6,E9) -> 162.776 | F11: =AVERAGE(F6,F9) -> 171.553 | G11: =AVERAGE(G6,G9) -> 182.608 | H11: =AVERAGE(H6,H9) -> 186.111 | I11: =AVERAGE(I6,I9) -> 194.261 | J11: =AVERAGE(J6,J9) -> 208.761 | ... L11: =AVERAGE(L6,L9) -> 214.461
A12: Container shipping volume | B12: TEU '000 | C12: 3142.118 | D12: 3261.939 | E12: 3224.498 | F12: 3570.184 | G12: 3847.539 | H12: =Interim!H6 -> 4053.7198 | I12: =H12*(1+Scenarios!I20) -> 4256.4058 | J12: =I12*(1+Scenarios!J20) -> 4469.2261 | K12: =J12*(1+Scenarios!K20) -> 4647.9951 | L12: =K12*(1+Scenarios!L20) -> 4810.675 | M12: Annual results; FY2026E = 9M26 actual + Q4 estimate (Interim tab)
A13: Volume growth | B13: % | C13: =C12/Inputs!$C$24-1 -> 0.20194109 | D13: =D12/C12-1 -> 0.038133832 | E13: =E12/D12-1 -> -0.011478142 | F13: =F12/E12-1 -> 0.10720614 | G13: =G12/F12-1 -> 0.077686472 | H13: =H12/G12-1 -> 0.053587709 | I13: =I12/H12-1 -> 0.05 | J13: =J12/I12-1 -> 0.05 | K13: =K12/J12-1 -> 0.04 | L13: =L12/K12-1 -> 0.035
A14: Liftings per average TEU slot | B14: x | C14: =C12/C11 -> 23.038843 | D14: =D12/D11 -> 21.33269 | E14: =E12/E11 -> 19.809419 | F14: =F12/F11 -> 20.810968 | G14: =G12/G11 -> 21.069937 | H14: =H12/H11 -> 21.781194 | I14: =I12/I11 -> 21.910758 | J14: =J12/J11 -> 21.408338 | ... L14: =L12/L11 -> 22.431468 | M14: Asset turns: volume / average capacity
A15: Average freight rate (excl. slot exchange) | B15: US$/TEU | C15: 826.9 | D15: 1099.6 | E15: 623.3 | F15: 721.1 | G15: 753.3 | H15: =Interim!H8 -> 831.27891 | I15: =H15*(1+Scenarios!I25) -> 748.15102 | J15: =I15*(1+Scenarios!J25) -> 710.74347 | K15: =J15*(1+Scenarios!K25) -> 710.74347 | L15: =K15*(1+Scenarios!L25) -> 717.85091
A16: Freight rate change | B16: % | C16: =C15/Inputs!$C$25-1 -> 0.51696936 | D16: =D15/C15-1 -> 0.32978595 | E16: =E15/D15-1 -> -0.43315751 | F16: =F15/E15-1 -> 0.15690679 | G16: =G15/F15-1 -> 0.044654001 | H16: =H15/G15-1 -> 0.10351641 | I16: =I15/H15-1 -> -0.1 | J16: =J15/I15-1 -> -0.05 | K16: =K15/J15-1 -> 0 | L16: =L15/K15-1 -> 0.01
A17: Freight revenue (volume x rate) | B17: US$m | C17: =C12*C15/1000 -> 2598.2174 | D17: =D12*D15/1000 -> 3586.8281 | E17: =E12*E15/1000 -> 2009.8296 | F17: =F12*F15/1000 -> 2574.4597 | G17: =G12*G15/1000 -> 2898.3511 | H17: =H12*H15/1000 -> 3369.7718 | I17: =I12*I15/1000 -> 3184.4343 | J17: =J12*J15/1000 -> 3176.4733 | ... L17: =L12*L15/1000 -> 3453.3474
A18: Slot exchange and other, % of freight revenue | B18: % | C18: =C19/C17 -> 0.040639643 | D18: =D19/D17 -> 0.062444273 | E18: =E19/E17 -> 0.093369307 | F18: =F19/F17 -> 0.062540625 | G18: =G19/G17 -> 0.061920334 | H18: =Scenarios!H48 -> 0.035 | I18: =Scenarios!I48 -> 0.035 | J18: =Scenarios!J48 -> 0.035 | K18: =Scenarios!K48 -> 0.035 | L18: =Scenarios!L48 -> 0.035
A19: Slot exchange, surcharges and other shipping income | B19: US$m | C19: =C20-C17 -> 105.59063 | D19: =D20-D17 -> 223.97688 | E19: =E20-E17 -> 187.6564 | F19: =F20-F17 -> 161.00832 | G19: =G20-G17 -> 179.46687 | H19: =H17*H18 -> 117.94201 | I19: =I17*I18 -> 111.4552 | J19: =J17*J18 -> 111.17656 | K19: =K17*K18 -> 115.62363 | L19: =L17*L18 -> 120.86716 | M19: Historical figures are the residual of reported shipping income
A20: Container shipping and supporting logistics income | B20: US$m | C20: 2703.808 | D20: 3810.805 | E20: 2197.486 | F20: 2735.468 | G20: 3077.818 | H20: =H17+H19 -> 3487.7138 | I20: =I17+I19 -> 3295.8895 | J20: =J17+J19 -> 3287.6498 | K20: =K17+K19 -> 3419.1558 | L20: =L17+L19 -> 3574.2145
A21: Growth | B21: % | D21: =D20/C20-1 -> 0.40942145 | E21: =E20/D20-1 -> -0.42335386 | F21: =F20/E20-1 -> 0.24481703 | G21: =G20/F20-1 -> 0.12515226 | H21: =H20/G20-1 -> 0.1331774 | I21: =I20/H20-1 -> -0.055 | J21: =J20/I20-1 -> -0.0025 | K21: =K20/J20-1 -> 0.04 | L21: =L20/K20-1 -> 0.04535
A22: Shipping income per TEU lifted | B22: US$/TEU | C22: =C20/C12*1000 -> 860.50492 | D22: =D20/D12*1000 -> 1168.2637 | E22: =E20/E12*1000 -> 681.49709 | F22: =F20/F12*1000 -> 766.19804 | G22: =G20/G12*1000 -> 799.94459 | H22: =H20/H12*1000 -> 860.37368 | I22: =I20/I12*1000 -> 774.33631 | J22: =J20/J12*1000 -> 735.61949 | ... L22: =L20/L12*1000 -> 742.97569
A23: Other container logistics income | B23: US$m | C23: 279.422 | D23: 291.418 | E23: 224.682 | F23: 320.394 | G23: 331.162 | H23: =G23*(1+Scenarios!H35) -> 404.01764 | I23: =H23*(1+Scenarios!I35) -> 428.2587 | J23: =I23*(1+Scenarios!J35) -> 449.67163 | K23: =J23*(1+Scenarios!K35) -> 472.15521 | L23: =K23*(1+Scenarios!L35) -> 491.04142 | M23: Freight forwarding, depots, warehousing, trucking
A24: Growth | B24: % | D24: =D23/C23-1 -> 0.04293148 | E24: =E23/D23-1 -> -0.22900439 | F24: =F23/E23-1 -> 0.42598873 | G24: =G23/F23-1 -> 0.033608619 | H24: =H23/G23-1 -> 0.22 | I24: =I23/H23-1 -> 0.06 | J24: =J23/I23-1 -> 0.05 | K24: =K23/J23-1 -> 0.05 | L24: =L23/K23-1 -> 0.04
A25: Logistics income per TEU lifted | B25: US$/TEU | C25: =C23/C12*1000 -> 88.927914 | D25: =D23/D12*1000 -> 89.338887 | E25: =E23/E12*1000 -> 69.679683 | F25: =F23/F12*1000 -> 89.741593 | G25: =G23/G12*1000 -> 86.071122 | H25: =H23/H12*1000 -> 99.665902 | I25: =I23/I12*1000 -> 100.6151 | J25: =J23/J12*1000 -> 100.6151 | ... L25: =L23/L12*1000 -> 102.07329
A26: Other sources (dry bulk and other) | B26: US$m | C26: 29.217 | D26: 10.732 | E26: 6.791 | F26: 2.197 | G26: 2.667 | H26: =Scenarios!H49 -> 2.6 | I26: =Scenarios!I49 -> 2.6 | J26: =Scenarios!J49 -> 2.6 | K26: =Scenarios!K49 -> 2.6 | L26: =Scenarios!L49 -> 2.6
A27: Total revenue | B27: US$m | C27: =C20+C23+C26 -> 3012.447 | D27: =D20+D23+D26 -> 4112.955 | E27: =E20+E23+E26 -> 2428.959 | F27: =F20+F23+F26 -> 3058.059 | G27: =G20+G23+G26 -> 3411.647 | H27: =H20+H23+H26 -> 3894.3314 | I27: =I20+I23+I26 -> 3726.7482 | J27: =J20+J23+J26 -> 3739.9215 | ... L27: =L20+L23+L26 -> 4067.856
A28: Revenue growth | B28: % | D28: =D27/C27-1 -> 0.36532029 | E28: =E27/D27-1 -> -0.40943701 | F28: =F27/E27-1 -> 0.25899984 | G28: =G27/F27-1 -> 0.11562498 | H28: =H27/G27-1 -> 0.14148136 | I28: =I27/H27-1 -> -0.043032598 | J28: =J27/I27-1 -> 0.0035347735 | K28: =K27/J27-1 -> 0.041174548 | L28: =L27/K27-1 -> 0.044671006
A29: Mix: container shipping | B29: % | C29: =C20/C27 -> 0.89754542 | D29: =D20/D27 -> 0.926537 | E29: =E20/E27 -> 0.9047028 | F29: =F20/F27 -> 0.89451119 | G29: =G20/G27 -> 0.90215019 | H29: =H20/H27 -> 0.89558731 | I29: =I20/I27 -> 0.8843875 | J29: =J20/J27 -> 0.87906922 | ... L29: =L20/L27 -> 0.87864825
A30: Mix: other container logistics | B30: % | C30: =C23/C27 -> 0.092755823 | D30: =D23/D27 -> 0.070853681 | E30: =E23/E27 -> 0.092501356 | F30: =F23/F27 -> 0.10477038 | G30: =G23/G27 -> 0.097068073 | H30: =H23/H27 -> 0.10374506 | I30: =I23/I27 -> 0.11491485 | J30: =J23/J27 -> 0.12023558 | ... L30: =L23/L27 -> 0.12071259
A31: Mix: other sources | B31: % | C31: =C26/C27 -> 0.0096987598 | D31: =D26/D27 -> 0.0026093162 | E31: =E26/E27 -> 0.0027958479 | F31: =F26/F27 -> 0.00071842957 | G31: =G26/G27 -> 0.00078173387 | H31: =H26/H27 -> 0.00066763706 | I31: =I26/I27 -> 0.00069765915 | J31: =J26/J27 -> 0.00069520177 | ... L31: =L26/L27 -> 0.00063915734
A32: Revenue per average TEU slot | B32: US$'000 | C32: =C27/C11 -> 22.088061 | D32: =D27/D11 -> 26.898233 | E32: =E27/E11 -> 14.922095 | F32: =F27/F11 -> 17.825739 | G32: =G27/G11 -> 18.6829 | H32: =H27/H11 -> 20.924778 | I32: =I27/I11 -> 19.184233 | J32: =J27/J11 -> 17.914847 | ... L32: =L27/L11 -> 18.967812
A34: B. Revenue by geography (location of service)
A35: Greater China | B35: US$m | C35: 1414.641 | D35: 1980.749 | E35: 942.529 | F35: 1473.885 | G35: 1653.596 | H35: =H27*H41 -> 1869.2791 | I35: =I27*I41 -> 1770.2054 | J35: =J27*J41 -> 1757.7631 | K35: =K27*K41 -> 1810.6686 | L35: =L27*L41 -> 1871.2137 | M35: Annual reports, geographical information
A36: Southeast Asia | B36: US$m | C36: 898.233 | D36: 1159.406 | E36: 790.401 | F36: 879.335 | G36: 983.042 | H36: =H27*H42 -> 1148.8278 | I36: =I27*I42 -> 1118.0245 | J36: =J27*J42 -> 1140.676 | K36: =K27*K42 -> 1207.1124 | L36: =L27*L42 -> 1281.3746
A37: Japan | B37: US$m | C37: 579.265 | D37: 742.682 | E37: 527.012 | F37: 520.96 | G37: 596.799 | H37: =H27*H43 -> 673.71934 | I37: =I27*I43 -> 641.0007 | J37: =J27*J43 -> 639.52657 | K37: =K27*K43 -> 661.96488 | L37: =L27*L43 -> 691.53551
A38: Others | B38: US$m | C38: 120.308 | D38: 230.118 | E38: 169.017 | F38: 183.879 | G38: 178.21 | H38: =H27*H44 -> 202.50524 | I38: =I27*I44 -> 197.51766 | J38: =J27*J44 -> 201.95576 | K38: =K27*K44 -> 214.16511 | L38: =L27*L44 -> 223.73208
A39: Total revenue by geography | B39: US$m | C39: =C35+C36+C37+C38 -> 3012.447 | D39: =D35+D36+D37+D38 -> 4112.955 | E39: =E35+E36+E37+E38 -> 2428.959 | F39: =F35+F36+F37+F38 -> 3058.059 | G39: =G35+G36+G37+G38 -> 3411.647 | H39: =H35+H36+H37+H38 -> 3894.3314 | I39: =I35+I36+I37+I38 -> 3726.7482 | J39: =J35+J36+J37+J38 -> 3739.9215 | ... L39: =L35+L36+L37+L38 -> 4067.856
A40: Difference to total revenue | B40: US$m | C40: =ROUND(C39-C27,3) -> 0 | D40: =ROUND(D39-D27,3) -> 0 | E40: =ROUND(E39-E27,3) -> 0 | F40: =ROUND(F39-F27,3) -> 0 | G40: =ROUND(G39-G27,3) -> 0 | H40: =ROUND(H39-H27,3) -> 0 | I40: =ROUND(I39-I27,3) -> 0 | J40: =ROUND(J39-J27,3) -> 0 | ... L40: =ROUND(L39-L27,3) -> 0
A41: Greater China share | B41: % | C41: =C35/C39 -> 0.46959864 | D41: =D35/D39 -> 0.48158781 | E41: =E35/E39 -> 0.38803825 | F41: =F35/F39 -> 0.48196748 | G41: =G35/G39 -> 0.48469141 | H41: =Scenarios!H50 -> 0.48 | I41: =Scenarios!I50 -> 0.475 | J41: =Scenarios!J50 -> 0.47 | K41: =Scenarios!K50 -> 0.465 | L41: =Scenarios!L50 -> 0.46
A42: Southeast Asia share | B42: % | C42: =C36/C39 -> 0.29817388 | D42: =D36/D39 -> 0.28189124 | E42: =E36/E39 -> 0.3254073 | F42: =F36/F39 -> 0.28754677 | G42: =G36/G39 -> 0.28814294 | H42: =Scenarios!H51 -> 0.295 | I42: =Scenarios!I51 -> 0.3 | J42: =Scenarios!J51 -> 0.305 | K42: =Scenarios!K51 -> 0.31 | L42: =Scenarios!L51 -> 0.315
...

Sheet Income Statement
A1: SITC International Holdings (1308.HK) - Income Statement
A2: Consolidated income statement, FY2021A-FY2030E. US$m unless stated; costs negative.
A4: US$m unless stated | B4: Unit | C4: FY2021A | D4: FY2022A | E4: FY2023A | F4: FY2024A | G4: FY2025A | H4: FY2026E | I4: FY2027E | J4: FY2028E | K4: FY2029E | L4: FY2030E | M4: Source / assumption
A5: Revenue
A6: Container shipping and supporting logistics income | B6: US$m | C6: ='Revenue Model'!C20 -> 2703.808 | D6: ='Revenue Model'!D20 -> 3810.805 | E6: ='Revenue Model'!E20 -> 2197.486 | F6: ='Revenue Model'!F20 -> 2735.468 | G6: ='Revenue Model'!G20 -> 3077.818 | H6: ='Revenue Model'!H20 -> 3487.7138 | I6: ='Revenue Model'!I20 -> 3295.8895 | J6: ='Revenue Model'!J20 -> 3287.6498 | ... L6: ='Revenue Model'!L20 -> 3574.2145
A7: Other container logistics income | B7: US$m | C7: ='Revenue Model'!C23 -> 279.422 | D7: ='Revenue Model'!D23 -> 291.418 | E7: ='Revenue Model'!E23 -> 224.682 | F7: ='Revenue Model'!F23 -> 320.394 | G7: ='Revenue Model'!G23 -> 331.162 | H7: ='Revenue Model'!H23 -> 404.01764 | I7: ='Revenue Model'!I23 -> 428.2587 | J7: ='Revenue Model'!J23 -> 449.67163 | ... L7: ='Revenue Model'!L23 -> 491.04142
A8: Other sources | B8: US$m | C8: ='Revenue Model'!C26 -> 29.217 | D8: ='Revenue Model'!D26 -> 10.732 | E8: ='Revenue Model'!E26 -> 6.791 | F8: ='Revenue Model'!F26 -> 2.197 | G8: ='Revenue Model'!G26 -> 2.667 | H8: ='Revenue Model'!H26 -> 2.6 | I8: ='Revenue Model'!I26 -> 2.6 | J8: ='Revenue Model'!J26 -> 2.6 | ... L8: ='Revenue Model'!L26 -> 2.6
A9: Total revenue | B9: US$m | C9: =C6+C7+C8 -> 3012.447 | D9: =D6+D7+D8 -> 4112.955 | E9: =E6+E7+E8 -> 2428.959 | F9: =F6+F7+F8 -> 3058.059 | G9: =G6+G7+G8 -> 3411.647 | H9: =H6+H7+H8 -> 3894.3314 | I9: =I6+I7+I8 -> 3726.7482 | J9: =J6+J7+J8 -> 3739.9215 | ... L9: =L6+L7+L8 -> 4067.856
A10: Growth | B10: % | D10: =D9/C9-1 -> 0.36532029 | E10: =E9/D9-1 -> -0.40943701 | F10: =F9/E9-1 -> 0.25899984 | G10: =G9/F9-1 -> 0.11562498 | H10: =H9/G9-1 -> 0.14148136 | I10: =I9/H9-1 -> -0.043032598 | J10: =J9/I9-1 -> 0.0035347735 | K10: =K9/J9-1 -> 0.041174548 | L10: =L9/K9-1 -> 0.044671006
A11: Cost of sales
A12: Equipment and cargo transportation costs | B12: US$m | C12: -853.83 | D12: -1010.115 | E12: -925.542 | F12: -973.133 | G12: -1093.166 | H12: =-'Revenue Model'!H12*H21/1000 -> -1118.8267 | I12: =-'Revenue Model'!I12*I21/1000 -> -1192.3895 | J12: =-'Revenue Model'!J12*J21/1000 -> -1270.7891 | K12: =-'Revenue Model'!K12*K21/1000 -> -1341.445 | L12: =-'Revenue Model'!L12*L21/1000 -> -1409.2215 | M12: Annual results; FY2023 derived as total cost of sales less the other lines
A13: Voyage costs (bunker, port charges) | B13: US$m | C13: -350.506 | D13: -542.194 | E13: -408.463 | F13: -422.468 | G13: -402.446 | H13: =-'Revenue Model'!H12*H22/1000 -> -468.20464 | I13: =-'Revenue Model'!I12*I22/1000 -> -476.86642 | J13: =-'Revenue Model'!J12*J22/1000 -> -500.70974 | K13: =-'Revenue Model'!K12*K22/1000 -> -525.94551 | L13: =-'Revenue Model'!L12*L22/1000 -> -549.79714
A14: Container shipping vessel costs (depreciation, charter hire, crew) | B14: US$m | C14: -258.686 | D14: -355.962 | E14: -296.734 | F14: -257.47 | G14: -329.426 | H14: =-'Revenue Model'!H11*H23/1000 -> -364.77756 | I14: =-'Revenue Model'!I11*I23/1000 -> -373.13653 | J14: =-'Revenue Model'!J11*J23/1000 -> -396.97825 | K14: =-'Revenue Model'!K11*K23/1000 -> -415.54465 | L14: =-'Revenue Model'!L11*L23/1000 -> -418.07393
A15: Other container logistics costs | B15: US$m | C15: -212.26 | D15: -219.389 | E15: -172.472 | F15: -261.46 | G15: -274.528 | H15: =-'Revenue Model'!H23*H24 -> -335.33464 | I15: =-'Revenue Model'!I23*I24 -> -355.45472 | J15: =-'Revenue Model'!J23*J24 -> -373.22746 | K15: =-'Revenue Model'!K23*K24 -> -391.88883 | L15: =-'Revenue Model'!L23*L24 -> -407.56438
A16: Other costs | B16: US$m | C16: -17.792 | D16: -6.213 | E16: -2.714 | F16: -0.711 | G16: -1.615 | H16: =-'Revenue Model'!H26*H25 -> -1.56 | I16: =-'Revenue Model'!I26*I25 -> -1.56 | J16: =-'Revenue Model'!J26*J25 -> -1.56 | K16: =-'Revenue Model'!K26*K25 -> -1.56 | L16: =-'Revenue Model'!L26*L25 -> -1.56 | M16: FY2021-22: dry bulk cost of sales
A17: Total cost of sales | B17: US$m | C17: =SUM(C12:C16) -> -1693.074 | D17: =SUM(D12:D16) -> -2133.873 | E17: =SUM(E12:E16) -> -1805.925 | F17: =SUM(F12:F16) -> -1915.242 | G17: =SUM(G12:G16) -> -2101.181 | H17: =SUM(H12:H16) -> -2288.7035 | I17: =SUM(I12:I16) -> -2399.4072 | J17: =SUM(J12:J16) -> -2543.2646 | ... L17: =SUM(L12:L16) -> -2786.217
A18: Gross profit | B18: US$m | C18: =C9+C17 -> 1319.373 | D18: =D9+D17 -> 1979.082 | E18: =E9+E17 -> 623.034 | F18: =F9+F17 -> 1142.817 | G18: =G9+G17 -> 1310.466 | H18: =H9+H17 -> 1605.6279 | I18: =I9+I17 -> 1327.3411 | J18: =J9+J17 -> 1196.6569 | ... L18: =L9+L17 -> 1281.639
A19: Gross margin | B19: % | C19: =C18/C9 -> 0.43797385 | D19: =D18/D9 -> 0.48118251 | E19: =E18/E9 -> 0.25650248 | F19: =F18/F9 -> 0.37370666 | G19: =G18/G9 -> 0.38411536 | H19: =H18/H9 -> 0.41229874 | I19: =I18/I9 -> 0.35616601 | J19: =J18/J9 -> 0.31996845 | ... L19: =L18/L9 -> 0.31506499
A20: Unit costs (memo)
A21: Equipment and cargo cost per TEU | B21: US$/TEU | C21: =-C12/'Revenue Model'!C12*1000 -> 271.73709 | D21: =-D12/'Revenue Model'!D12*1000 -> 309.66704 | E21: =-E12/'Revenue Model'!E12*1000 -> 287.03445 | F21: =-F12/'Revenue Model'!F12*1000 -> 272.57223 | G21: =-G12/'Revenue Model'!G12*1000 -> 284.12084 | H21: =Scenarios!H54 -> 276 | I21: =H21*(1+Scenarios!I55) -> 280.14 | J21: =I21*(1+Scenarios!J55) -> 284.3421 | K21: =J21*(1+Scenarios!K55) -> 288.60723 | L21: =K21*(1+Scenarios!L55) -> 292.93634
A22: Voyage cost per TEU | B22: US$/TEU | C22: =-C13/'Revenue Model'!C12*1000 -> 111.55087 | D22: =-D13/'Revenue Model'!D12*1000 -> 166.21831 | E22: =-E13/'Revenue Model'!E12*1000 -> 126.67491 | F22: =-F13/'Revenue Model'!F12*1000 -> 118.33228 | G22: =-G13/'Revenue Model'!G12*1000 -> 104.59829 | H22: =Scenarios!H56 -> 115.5 | I22: =H22*(1+Scenarios!I57) -> 112.035 | J22: =I22*(1+Scenarios!J57) -> 112.035 | K22: =J22*(1+Scenarios!K57) -> 113.15535 | L22: =K22*(1+Scenarios!L57) -> 114.2869
A23: Vessel cost per average TEU slot | B23: US$/slot | C23: =-C14/'Revenue Model'!C11*1000 -> 1896.7544 | D23: =-D14/'Revenue Model'!D11*1000 -> 2327.9488 | E23: =-E14/'Revenue Model'!E11*1000 -> 1822.9592 | F23: =-F14/'Revenue Model'!F11*1000 -> 1500.819 | G23: =-G14/'Revenue Model'!G11*1000 -> 1804.0064 | H23: =Scenarios!H58 -> 1960 | I23: =H23*(1+Scenarios!I30) -> 1920.8 | J23: =I23*(1+Scenarios!J30) -> 1901.592 | K23: =J23*(1+Scenarios!K30) -> 1920.6079 | L23: =K23*(1+Scenarios!L30) -> 1949.417
A24: Other logistics costs, % of logistics income | B24: % | C24: =-C15/C7 -> 0.75963954 | D24: =-D15/D7 -> 0.7528327 | E24: =-E15/E7 -> 0.76762714 | F24: =-F15/F7 -> 0.81605773 | G24: =-G15/G7 -> 0.828984 | H24: =Scenarios!H59 -> 0.83 | I24: =Scenarios!I59 -> 0.83 | J24: =Scenarios!J59 -> 0.83 | K24: =Scenarios!K59 -> 0.83 | L24: =Scenarios!L59 -> 0.83
A25: Other costs, % of other sources revenue | B25: % | C25: =-C16/C8 -> 0.60896054 | D25: =-D16/D8 -> 0.57892285 | E25: =-E16/E8 -> 0.39964659 | F25: =-F16/F8 -> 0.32362312 | G25: =-G16/G8 -> 0.60554931 | H25: =Scenarios!H60 -> 0.6 | I25: =Scenarios!I60 -> 0.6 | J25: =Scenarios!J60 -> 0.6 | K25: =Scenarios!K60 -> 0.6 | L25: =Scenarios!L60 -> 0.6
A26: Total cost of sales per TEU lifted | B26: US$/TEU | C26: =-C17/'Revenue Model'!C12*1000 -> 538.83209 | D26: =-D17/'Revenue Model'!D12*1000 -> 654.17318 | E26: =-E17/'Revenue Model'!E12*1000 -> 560.06392 | F26: =-F17/'Revenue Model'!F12*1000 -> 536.4547 | G26: =-G17/'Revenue Model'!G12*1000 -> 546.11038 | H26: =-H17/'Revenue Model'!H12*1000 -> 564.59341 | I26: =-I17/'Revenue Model'!I12*1000 -> 563.71674 | J26: =-J17/'Revenue Model'!J12*1000 -> 569.06152 | ... L26: =-L17/'Revenue Model'!L12*1000 -> 579.17382
A27: Gross profit per TEU lifted | B27: US$/TEU | C27: =C18/'Revenue Model'!C12*1000 -> 419.89925 | D27: =D18/'Revenue Model'!D12*1000 -> 606.7195 | E27: =E18/'Revenue Model'!E12*1000 -> 193.21891 | F27: =F18/'Revenue Model'!F12*1000 -> 320.10031 | G27: =G18/'Revenue Model'!G12*1000 -> 340.5985 | H27: =H18/'Revenue Model'!H12*1000 -> 396.08755 | I27: =I18/'Revenue Model'!I12*1000 -> 311.84552 | J27: =J18/'Revenue Model'!J12*1000 -> 267.75483 | ... L27: =L18/'Revenue Model'!L12*1000 -> 266.41563
A28: Operating items
A29: Gain on disposal of vessels and equipment | B29: US$m | C29: 3.141 | D29: 119.072 | E29: 22.05 | F29: 9.524 | G29: 35.527 | H29: =Scenarios!H63 -> 10 | I29: =Scenarios!I63 -> 5 | J29: =Scenarios!J63 -> 5 | K29: =Scenarios!K63 -> 5 | L29: =Scenarios!L63 -> 5
A30: Other income and gains | B30: US$m | C30: 14.588 | D30: 18.72 | E30: 16.125 | F30: 8.451 | G30: 9.5 | H30: =Scenarios!H65 -> 12 | I30: =Scenarios!I65 -> 10 | J30: =Scenarios!J65 -> 10 | K30: =Scenarios!K65 -> 10 | L30: =Scenarios!L65 -> 10 | M30: Residual of reported other income and gains
A31: Administrative expenses | B31: US$m | C31: -154.764 | D31: -165.651 | E31: -136.047 | F31: -143.998 | G31: -153.578 | H31: =G31*(1+Scenarios!H66) -> -173.54314 | I31: =H31*(1+Scenarios!I66) -> -182.2203 | J31: =I31*(1+Scenarios!J66) -> -189.50911 | K31: =J31*(1+Scenarios!K66) -> -197.08947 | L31: =K31*(1+Scenarios!L66) -> -204.97305
A32: Administrative expenses, % of revenue | B32: % | C32: =-C31/C9 -> 0.051374846 | D32: =-D31/D9 -> 0.040275422 | E32: =-E31/E9 -> 0.056010414 | F32: =-F31/F9 -> 0.047088039 | G32: =-G31/G9 -> 0.045015794 | H32: =-H31/H9 -> 0.044563012 | I32: =-I31/I9 -> 0.048895253 | J32: =-J31/J9 -> 0.050671949 | ... L32: =-L31/L9 -> 0.050388473
A33: Other expenses, net | B33: US$m | C33: -4.493 | D33: -5.383 | E33: -4.085 | F33: -0.952 | G33: -5.686 | H33: =-Scenarios!H67 -> -4 | I33: =-Scenarios!I67 -> -4 | J33: =-Scenarios!J67 -> -4 | K33: =-Scenarios!K67 -> -4 | L33: =-Scenarios!L67 -> -4
A34: EBIT (excl. JVs, associates and interest income) | B34: US$m | C34: =C18+C29+C30+C31+C33 -> 1177.845 | D34: =D18+D29+D30+D31+D33 -> 1945.84 | E34: =E18+E29+E30+E31+E33 -> 521.077 | F34: =F18+F29+F30+F31+F33 -> 1015.842 | G34: =G18+G29+G30+G31+G33 -> 1196.229 | H34: =H18+H29+H30+H31+H33 -> 1450.0848 | I34: =I18+I29+I30+I31+I33 -> 1156.1208 | J34: =J18+J29+J30+J31+J33 -> 1018.1478 | ... L34: =L18+L29+L30+L31+L33 -> 1087.6659
A35: EBIT margin | B35: % | C35: =C34/C9 -> 0.39099277 | D35: =D34/D9 -> 0.47310024 | E35: =E34/E9 -> 0.21452688 | F35: =F34/F9 -> 0.33218522 | G35: =G34/G9 -> 0.35063094 | H35: =H34/H9 -> 0.37235783 | I35: =I34/I9 -> 0.31022239 | J35: =J34/J9 -> 0.27223774 | ... L35: =L34/L9 -> 0.26738064
A36: Depreciation of PPE | B36: US$m | C36: 79.239 | D36: 88.312 | E36: 99.973 | F36: 110.999 | G36: 116.014 | H36: =Scenarios!H76*'Balance Sheet'!G6 -> 114.77504 | I36: =Scenarios!I76*'Balance Sheet'!H6 -> 111.49984 | J36: =Scenarios!J76*'Balance Sheet'!I6 -> 129.86145 | K36: =Scenarios!K76*'Balance Sheet'!J6 -> 150.47832 | L36: =Scenarios!L76*'Balance Sheet'!K6 -> 149.36482 | M36: Mostly within vessel costs in cost of sales
A37: Depreciation of right-of-use assets | B37: US$m | C37: 52.135 | D37: 57.332 | E37: 58.788 | F37: 52.913 | G37: 64.231 | H37: =Scenarios!H77*'Balance Sheet'!G7 -> 68.49024 | I37: =Scenarios!I77*'Balance Sheet'!H7 -> 68.80729 | J37: =Scenarios!J77*'Balance Sheet'!I7 -> 70.107759 | K37: =Scenarios!K77*'Balance Sheet'!J7 -> 71.135129 | L37: =Scenarios!L77*'Balance Sheet'!K7 -> 71.946752
A38: Depreciation and amortisation | B38: US$m | C38: =C36+C37 -> 131.374 | D38: =D36+D37 -> 145.644 | E38: =E36+E37 -> 158.761 | F38: =F36+F37 -> 163.912 | G38: =G36+G37 -> 180.245 | H38: =H36+H37 -> 183.26528 | I38: =I36+I37 -> 180.30713 | J38: =J36+J37 -> 199.96921 | ... L38: =L36+L37 -> 221.31158
A39: EBITDA | B39: US$m | C39: =C34+C38 -> 1309.219 | D39: =D34+D38 -> 2091.484 | E39: =E34+E38 -> 679.838 | F39: =F34+F38 -> 1179.754 | G39: =G34+G38 -> 1376.474 | H39: =H34+H38 -> 1633.3501 | I39: =I34+I38 -> 1336.4279 | J39: =J34+J38 -> 1218.117 | ... L39: =L34+L38 -> 1308.9775
A40: EBITDA margin | B40: % | C40: =C39/C9 -> 0.43460316 | D40: =D39/D9 -> 0.50851128 | E40: =E39/E9 -> 0.27988863 | F40: =F39/F9 -> 0.38578523 | G40: =G39/G9 -> 0.4034632 | H40: =H39/H9 -> 0.41941733 | I40: =I39/I9 -> 0.35860428 | J40: =J39/J9 -> 0.32570657 | ... L40: =L39/L9 -> 0.32178561
A41: Share of profits of joint ventures | B41: US$m | C41: 15.578 | D41: 21.706 | E41: 20.013 | F41: 24.503 | G41: 31.08 | H41: =G41*(1+Scenarios!H69) -> 36.0528 | I41: =H41*(1+Scenarios!I69) -> 37.494912 | J41: =I41*(1+Scenarios!J69) -> 38.619759 | K41: =J41*(1+Scenarios!K69) -> 39.778352 | L41: =K41*(1+Scenarios!L69) -> 40.971703
...

Sheet Cash Flow
A1: SITC International Holdings (1308.HK) - Cash Flow
A2: Consolidated cash flow statement; outflows negative. US$m.
A4: US$m unless stated | B4: Unit | C4: FY2021A | D4: FY2022A | E4: FY2023A | F4: FY2024A | G4: FY2025A | H4: FY2026E | I4: FY2027E | J4: FY2028E | K4: FY2029E | L4: FY2030E | M4: Source / assumption
A5: Operating activities
A6: Profit for the year | B6: US$m | C6: ='Income Statement'!C49 -> 1167.179 | D6: ='Income Statement'!D49 -> 1949.807 | E6: ='Income Statement'!E49 -> 536.174 | F6: ='Income Statement'!F49 -> 1034.342 | G6: ='Income Statement'!G49 -> 1230.402 | H6: ='Income Statement'!H49 -> 1481.2793 | I6: ='Income Statement'!I49 -> 1191.1713 | J6: ='Income Statement'!J49 -> 1055.7199 | ... L6: ='Income Statement'!L49 -> 1131.103
A7: Depreciation and amortisation | B7: US$m | C7: ='Income Statement'!C38 -> 131.374 | D7: ='Income Statement'!D38 -> 145.644 | E7: ='Income Statement'!E38 -> 158.761 | F7: ='Income Statement'!F38 -> 163.912 | G7: ='Income Statement'!G38 -> 180.245 | H7: ='Income Statement'!H38 -> 183.26528 | I7: ='Income Statement'!I38 -> 180.30713 | J7: ='Income Statement'!J38 -> 199.96921 | ... L7: ='Income Statement'!L38 -> 221.31158
A8: Share award expense | B8: US$m | C8: ='Income Statement'!C62 -> 8.444 | D8: ='Income Statement'!D62 -> 27.747 | E8: ='Income Statement'!E62 -> 28.429 | F8: ='Income Statement'!F62 -> 27.829 | G8: ='Income Statement'!G62 -> 26.952 | H8: ='Income Statement'!H62 -> 25 | I8: ='Income Statement'!I62 -> 25 | J8: ='Income Statement'!J62 -> 25 | ... L8: ='Income Statement'!L62 -> 25
A9: Share of JV and associate profits | B9: US$m | C9: =-('Income Statement'!C41+'Income Statement'!C42) -> -15.946 | D9: =-('Income Statement'!D41+'Income Statement'!D42) -> -22.167 | E9: =-('Income Statement'!E41+'Income Statement'!E42) -> -19.8 | F9: =-('Income Statement'!F41+'Income Statement'!F42) -> -26.381 | G9: =-('Income Statement'!G41+'Income Statement'!G42) -> -32.759 | H9: =-('Income Statement'!H41+'Income Statement'!H42) -> -37.5528 | I9: =-('Income Statement'!I41+'Income Statement'!I42) -> -38.994912 | J9: =-('Income Statement'!J41+'Income Statement'!J42) -> -40.119759 | ... L9: =-('Income Statement'!L41+'Income Statement'!L42) -> -42.471703
A10: Gain on disposal of vessels and equipment | B10: US$m | C10: =-'Income Statement'!C29 -> -3.141 | D10: =-'Income Statement'!D29 -> -119.072 | E10: =-'Income Statement'!E29 -> -22.05 | F10: =-'Income Statement'!F29 -> -9.524 | G10: =-'Income Statement'!G29 -> -35.527 | H10: =-'Income Statement'!H29 -> -10 | I10: =-'Income Statement'!I29 -> -5 | J10: =-'Income Statement'!J29 -> -5 | ... L10: =-'Income Statement'!L29 -> -5
A11: Change in bunkers | B11: US$m | H11: ='Balance Sheet'!G16-'Balance Sheet'!H16 -> -6.3698593 | I11: ='Balance Sheet'!H16-'Balance Sheet'!I16 -> -1.0678914 | J11: ='Balance Sheet'!I16-'Balance Sheet'!J16 -> -2.9395875 | K11: ='Balance Sheet'!J16-'Balance Sheet'!K16 -> -3.1112594 | L11: ='Balance Sheet'!K16-'Balance Sheet'!L16 -> -2.9406118
A12: Change in trade receivables | B12: US$m | H12: ='Balance Sheet'!G17-'Balance Sheet'!H17 -> -39.995426 | I12: ='Balance Sheet'!H17-'Balance Sheet'!I17 -> 9.6417732 | J12: ='Balance Sheet'!I17-'Balance Sheet'!J17 -> -0.75791077 | K12: ='Balance Sheet'!J17-'Balance Sheet'!K17 -> -8.8596742 | L12: ='Balance Sheet'!K17-'Balance Sheet'!L17 -> -10.00779
A13: Change in prepayments and other receivables | B13: US$m | H13: ='Balance Sheet'!G18-'Balance Sheet'!H18 -> -11.608309 | I13: ='Balance Sheet'!H18-'Balance Sheet'!I18 -> 2.1785816 | J13: ='Balance Sheet'!I18-'Balance Sheet'!J18 -> -0.17125174 | K13: ='Balance Sheet'!J18-'Balance Sheet'!K18 -> -2.0018645 | L13: ='Balance Sheet'!K18-'Balance Sheet'!L18 -> -2.261284
A14: Change in trade payables | B14: US$m | H14: ='Balance Sheet'!H26-'Balance Sheet'!G26 -> 21.843243 | I14: ='Balance Sheet'!I26-'Balance Sheet'!H26 -> 12.435209 | J14: ='Balance Sheet'!J26-'Balance Sheet'!I26 -> 16.159323 | K14: ='Balance Sheet'!K26-'Balance Sheet'!J26 -> 14.953141 | L14: ='Balance Sheet'!L26-'Balance Sheet'!K26 -> 12.337402
A15: Change in other payables and accruals | B15: US$m | H15: ='Balance Sheet'!H27-'Balance Sheet'!G27 -> 18.101578 | I15: ='Balance Sheet'!I27-'Balance Sheet'!H27 -> -7.8764105 | J15: ='Balance Sheet'!J27-'Balance Sheet'!I27 -> 0.61914092 | K15: ='Balance Sheet'!K27-'Balance Sheet'!J27 -> 7.23751 | L15: ='Balance Sheet'!L27-'Balance Sheet'!K27 -> 8.1754115
A16: Change in income tax payable | B16: US$m | H16: ='Balance Sheet'!H31-'Balance Sheet'!G31 -> 1.2424482 | I16: ='Balance Sheet'!I31-'Balance Sheet'!H31 -> -1.0034253 | J16: ='Balance Sheet'!J31-'Balance Sheet'!I31 -> -0.46849934 | K16: ='Balance Sheet'!K31-'Balance Sheet'!J31 -> 0.045807893 | L16: ='Balance Sheet'!L31-'Balance Sheet'!K31 -> 0.21492737
A17: Working capital and other items (historical residual) | B17: US$m | C17: 47.299 | D17: 20.606 | E17: -9.301 | F17: -31.844 | G17: 31.724 | M17: Reported operating cash flow less the lines above
A18: Net cash from operating activities | B18: US$m | C18: =SUM(C6:C17) -> 1335.209 | D18: =SUM(D6:D17) -> 2002.565 | E18: =SUM(E6:E17) -> 672.213 | F18: =SUM(F6:F17) -> 1158.334 | G18: =SUM(G6:G17) -> 1401.037 | H18: =SUM(H6:H17) -> 1625.2054 | I18: =SUM(I6:I17) -> 1366.7914 | J18: =SUM(J6:J17) -> 1248.0105 | ... L18: =SUM(L6:L17) -> 1335.461
A19: Investing activities
A20: Purchases of PPE (FY2026E on: containers, equipment, dry-docking) | B20: US$m | C20: -67.996 | D20: -412.832 | E20: -260.645 | F20: -242.939 | G20: -100.207 | H20: =-Scenarios!H83 -> -30 | I20: =-Scenarios!I83 -> -60 | J20: =-Scenarios!J83 -> -60 | K20: =-Scenarios!K83 -> -60 | L20: =-Scenarios!L83 -> -60
A21: Advance payments for vessels (newbuild instalments) | B21: US$m | C21: -121.103 | D21: -75.34 | E21: -48.511 | F21: -18.087 | G21: -35.122 | H21: =-(Scenarios!H81+Scenarios!H82) -> -132 | I21: =-(Scenarios!I81+Scenarios!I82) -> -330 | J21: =-(Scenarios!J81+Scenarios!J82) -> -300 | K21: =-(Scenarios!K81+Scenarios!K82) -> -148.1 | L21: =-(Scenarios!L81+Scenarios!L82) -> -150
A22: Proceeds from disposal of vessels and equipment | B22: US$m | C22: 20.978 | D22: 241.744 | E22: 44.067 | F22: 32.374 | G22: 70.732 | H22: =Scenarios!H64 -> 30 | I22: =Scenarios!I64 -> 15 | J22: =Scenarios!J64 -> 15 | K22: =Scenarios!K64 -> 15 | L22: =Scenarios!L64 -> 15
A23: Dividends from joint ventures | B23: US$m | C23: 2.986 | D23: 12.239 | E23: 15.246 | F23: 17.316 | G23: 27.603 | H23: ='Income Statement'!H41*Scenarios!H71 -> 30.64488 | I23: ='Income Statement'!I41*Scenarios!I71 -> 31.870675 | J23: ='Income Statement'!J41*Scenarios!J71 -> 32.826795 | K23: ='Income Statement'!K41*Scenarios!K71 -> 33.811599 | L23: ='Income Statement'!L41*Scenarios!L71 -> 34.825947
A24: Change in time deposits and FVTPL assets | B24: US$m | H24: =('Balance Sheet'!G21+'Balance Sheet'!G20)-('Balance Sheet'!H21+'Balance Sheet'!H20) -> -19.97 | I24: =('Balance Sheet'!H21+'Balance Sheet'!H20)-('Balance Sheet'!I21+'Balance Sheet'!I20) -> 0 | J24: =('Balance Sheet'!I21+'Balance Sheet'!I20)-('Balance Sheet'!J21+'Balance Sheet'!J20) -> 0 | K24: =('Balance Sheet'!J21+'Balance Sheet'!J20)-('Balance Sheet'!K21+'Balance Sheet'!K20) -> 0 | L24: =('Balance Sheet'!K21+'Balance Sheet'!K20)-('Balance Sheet'!L21+'Balance Sheet'!L20) -> 0
A25: Deposits, investments and other (historical residual) | B25: US$m | C25: 218.954 | D25: -195.006 | E25: 100.658 | F25: -298.212 | G25: -91.455
A26: Net cash from investing activities | B26: US$m | C26: =SUM(C20:C25) -> 53.819 | D26: =SUM(D20:D25) -> -429.195 | E26: =SUM(E20:E25) -> -149.185 | F26: =SUM(F20:F25) -> -509.548 | G26: =SUM(G20:G25) -> -128.449 | H26: =SUM(H20:H25) -> -121.32512 | I26: =SUM(I20:I25) -> -343.12932 | J26: =SUM(J20:J25) -> -312.1732 | ... L26: =SUM(L20:L25) -> -160.17405
A27: Financing activities
A28: Dividends paid to shareholders | B28: US$m | C28: -551.911 | D28: -1574.077 | E28: -751.971 | F28: -557.55 | G28: -937.716 | H28: =-(H50+'Balance Sheet'!G32-'Balance Sheet'!H32) -> -1451.9051 | I28: =-(I50+'Balance Sheet'!H32-'Balance Sheet'!I32) -> -908.00141 | J28: =-(J50+'Balance Sheet'!I32-'Balance Sheet'!J32) -> -887.97839 | K28: =-(K50+'Balance Sheet'!J32-'Balance Sheet'!K32) -> -845.30079 | L28: =-(L50+'Balance Sheet'!K32-'Balance Sheet'!L32) -> -877.21722
A29: Dividends paid to non-controlling interests | B29: US$m | H29: ='Income Statement'!H51*Scenarios!H97 -> -2.6663027 | I29: ='Income Statement'!I51*Scenarios!I97 -> -2.1441083 | J29: ='Income Statement'!J51*Scenarios!J97 -> -1.9002958 | K29: ='Income Statement'!K51*Scenarios!K97 -> -1.9241347 | L29: ='Income Statement'!L51*Scenarios!L97 -> -2.0359855
A30: Principal portion of lease payments | B30: US$m | C30: -56.129 | D30: -63.028 | E30: -63.728 | F30: -61.237 | G30: -77.909 | H30: =-'Income Statement'!H37*Scenarios!H79 -> -76.709069 | I30: =-'Income Statement'!I37*Scenarios!I79 -> -77.064164 | J30: =-'Income Statement'!J37*Scenarios!J79 -> -78.52069 | K30: =-'Income Statement'!K37*Scenarios!K79 -> -79.671345 | L30: =-'Income Statement'!L37*Scenarios!L79 -> -80.580363
A31: New bank loans | B31: US$m | C31: 70.7 | D31: 110.067 | E31: 95.171 | F31: 31.132 | G31: 19.766
A32: Repayment of bank loans | B32: US$m | C32: -167.661 | D32: -166.336 | E32: -198.313 | F32: -33.136 | G32: -168.26
A33: Net change in existing bank loans | B33: US$m | H33: ='Balance Sheet'!H29-'Balance Sheet'!G29 -> 11.061 | I33: ='Balance Sheet'!I29-'Balance Sheet'!H29 -> -30 | J33: ='Balance Sheet'!J29-'Balance Sheet'!I29 -> 0 | K33: ='Balance Sheet'!K29-'Balance Sheet'!J29 -> 0 | L33: ='Balance Sheet'!L29-'Balance Sheet'!K29 -> 0
A34: Purchase of shares for the share scheme | B34: US$m | C34: -48.112 | D34: -22.013 | E34: -23.753 | F34: -5.083 | G34: -0.914 | H34: =-Scenarios!H96 -> -5 | I34: =-Scenarios!I96 -> -5 | J34: =-Scenarios!J96 -> -5 | K34: =-Scenarios!K96 -> -5 | L34: =-Scenarios!L96 -> -5
A35: Other financing (historical residual: NCI dividends, option proceeds) | B35: US$m | C35: -1.097 | D35: -2.862 | E35: -2.018 | F35: -7.665 | G35: -5.735
A36: Financing cash flow before revolver | B36: US$m | C36: =SUM(C28:C35) -> -754.21 | D36: =SUM(D28:D35) -> -1718.249 | E36: =SUM(E28:E35) -> -944.612 | F36: =SUM(F28:F35) -> -633.539 | G36: =SUM(G28:G35) -> -1170.768 | H36: =SUM(H28:H35) -> -1525.2195 | I36: =SUM(I28:I35) -> -1022.2097 | J36: =SUM(J28:J35) -> -973.39937 | ... L36: =SUM(L28:L35) -> -964.83356
A37: Revolver drawdown / (repayment) | B37: US$m | H37: =H45-G45 -> 0 | I37: =I45-H45 -> 0 | J37: =J45-I45 -> 0 | K37: =K45-J45 -> 0 | L37: =L45-K45 -> 0
A38: Net cash from financing activities | B38: US$m | C38: =C36+C37 -> -754.21 | D38: =D36+D37 -> -1718.249 | E38: =E36+E37 -> -944.612 | F38: =F36+F37 -> -633.539 | G38: =G36+G37 -> -1170.768 | H38: =H36+H37 -> -1525.2195 | I38: =I36+I37 -> -1022.2097 | J38: =J36+J37 -> -973.39937 | ... L38: =L36+L37 -> -964.83356
A39: Effect of exchange rate changes (historical) | B39: US$m | C39: -1.693 | D39: -4.722 | E39: -0.869 | F39: -1.364 | G39: 5.671
A40: Net change in cash and cash equivalents | B40: US$m | C40: =C18+C26+C38+C39 -> 633.125 | D40: =D18+D26+D38+D39 -> -149.601 | E40: =E18+E26+E38+E39 -> -422.453 | F40: =F18+F26+F38+F39 -> 13.883 | G40: =G18+G26+G38+G39 -> 107.491 | H40: =H18+H26+H38+H39 -> -21.339193 | I40: =I18+I26+I38+I39 -> 1.4523492 | J40: =J18+J26+J38+J39 -> -37.562035 | ... L40: =L18+L26+L38+L39 -> 210.45335
A41: Cash and cash equivalents, start of year | B41: US$m | C41: =Inputs!$C$26 -> 61.139 | D41: =C42 -> 694.264 | E41: =D42 -> 544.663 | F41: =E42 -> 122.21 | G41: =F42 -> 136.093 | H41: =G42 -> 243.584 | I41: =H42 -> 222.24481 | J41: =I42 -> 223.69716 | K41: =J42 -> 186.13512 | L41: =K42 -> 372.51296
...

Sheet Balance Sheet
A1: SITC International Holdings (1308.HK) - Balance Sheet
A2: Consolidated statement of financial position at 31 December. US$m.
A4: US$m unless stated | B4: Unit | C4: FY2021A | D4: FY2022A | E4: FY2023A | F4: FY2024A | G4: FY2025A | H4: FY2026E | I4: FY2027E | J4: FY2028E | K4: FY2029E | L4: FY2030E | M4: Source / assumption
A5: Non-current assets
A6: Property, plant and equipment | B6: US$m | C6: 1087.704 | D6: 1396.647 | E6: 1661.852 | F6: 1827.726 | G6: 1793.36 | H6: =G6+Scenarios!H83+H50-'Income Statement'!H36-(Scenarios!H64-Scenarios!H63) -> 1742.185 | I6: =H6+Scenarios!I83+I50-'Income Statement'!I36-(Scenarios!I64-Scenarios!I63) -> 2029.0851 | J6: =I6+Scenarios!J83+J50-'Income Statement'!J36-(Scenarios!J64-Scenarios!J63) -> 2351.2237 | K6: =J6+Scenarios!K83+K50-'Income Statement'!K36-(Scenarios!K64-Scenarios!K63) -> 2333.8254 | L6: =K6+Scenarios!L83+L50-'Income Statement'!L36-(Scenarios!L64-Scenarios!L63) -> 2234.4605 | M6: Opening + other capex + newbuilds delivered - depreciation - NBV of disposals
A7: Right-of-use assets | B7: US$m | C7: 233.189 | D7: 262.923 | E7: 215.463 | F7: 235.841 | G7: 326.144 | H7: =G7+Scenarios!H78-'Income Statement'!H37 -> 327.65376 | I7: =H7+Scenarios!I78-'Income Statement'!I37 -> 333.84647 | J7: =I7+Scenarios!J78-'Income Statement'!J37 -> 338.73871 | K7: =J7+Scenarios!K78-'Income Statement'!K37 -> 342.60358 | L7: =K7+Scenarios!L78-'Income Statement'!L37 -> 345.65683
A8: Advance payments for vessels | B8: US$m | C8: 145.152 | D8: 111.722 | E8: 70.833 | F8: 30.873 | G8: 52.467 | H8: =G8+Scenarios!H81+Scenarios!H82-H50 -> 130.867 | I8: =H8+Scenarios!I81+Scenarios!I82-I50 -> 112.467 | J8: =I8+Scenarios!J81+Scenarios!J82-J50 -> 10.467 | K8: =J8+Scenarios!K81+Scenarios!K82-K50 -> 75.487 | L8: =K8+Scenarios!L81+Scenarios!L82-L50 -> 225.487
A9: Goodwill | B9: US$m | C9: 1.111 | D9: 1.019 | E9: 0.998 | F9: 0.971 | G9: 1.014 | H9: =G9 -> 1.014 | I9: =H9 -> 1.014 | J9: =I9 -> 1.014 | K9: =J9 -> 1.014 | L9: =K9 -> 1.014
A10: Other intangible assets | B10: US$m | C10: 1.579 | D10: 1.579 | E10: 1.579 | F10: 1.579 | G10: 1.579 | H10: =G10 -> 1.579 | I10: =H10 -> 1.579 | J10: =I10 -> 1.579 | K10: =J10 -> 1.579 | L10: =K10 -> 1.579
A11: Investments in joint ventures | B11: US$m | C11: 49.929 | D11: 57.777 | E11: 57.965 | F11: 60.666 | G11: 65.686 | H11: =G11+'Income Statement'!H41-'Cash Flow'!H23 -> 71.09392 | I11: =H11+'Income Statement'!I41-'Cash Flow'!I23 -> 76.718157 | J11: =I11+'Income Statement'!J41-'Cash Flow'!J23 -> 82.511121 | K11: =J11+'Income Statement'!K41-'Cash Flow'!K23 -> 88.477874 | L11: =K11+'Income Statement'!L41-'Cash Flow'!L23 -> 94.623629
A12: Investments in associates | B12: US$m | C12: 10.494 | D12: 9.63 | E12: 12.604 | F12: 13.892 | G12: 13.885 | H12: =G12+'Income Statement'!H42 -> 15.385 | I12: =H12+'Income Statement'!I42 -> 16.885 | J12: =I12+'Income Statement'!J42 -> 18.385 | K12: =J12+'Income Statement'!K42 -> 19.885 | L12: =K12+'Income Statement'!L42 -> 21.385
A13: Derivative financial instruments | B13: US$m | C13: 1.907 | D13: 12.589 | E13: 4.584 | F13: 3.006 | G13: 0 | H13: =G13 -> 0 | I13: =H13 -> 0 | J13: =I13 -> 0 | K13: =J13 -> 0 | L13: =K13 -> 0
A14: Total non-current assets | B14: US$m | C14: =SUM(C6:C13) -> 1531.065 | D14: =SUM(D6:D13) -> 1853.886 | E14: =SUM(E6:E13) -> 2025.878 | F14: =SUM(F6:F13) -> 2174.554 | G14: =SUM(G6:G13) -> 2254.135 | H14: =SUM(H6:H13) -> 2289.7776 | I14: =SUM(I6:I13) -> 2571.5947 | J14: =SUM(J6:J13) -> 2803.9185 | ... L14: =SUM(L6:L13) -> 2924.206
A15: Current assets
A16: Bunkers | B16: US$m | C16: 41.476 | D16: 53.205 | E16: 43.324 | F16: 46.98 | G16: 51.354 | H16: =-'Income Statement'!H13*Scenarios!H86/365 -> 57.723859 | I16: =-'Income Statement'!I13*Scenarios!I86/365 -> 58.791751 | J16: =-'Income Statement'!J13*Scenarios!J86/365 -> 61.731338 | K16: =-'Income Statement'!K13*Scenarios!K86/365 -> 64.842598 | L16: =-'Income Statement'!L13*Scenarios!L86/365 -> 67.78321
A17: Trade receivables | B17: US$m | C17: 157.038 | D17: 139.051 | E17: 113.333 | F17: 174.671 | G17: 184.062 | H17: ='Income Statement'!H9*Scenarios!H85/365 -> 224.05743 | I17: ='Income Statement'!I9*Scenarios!I85/365 -> 214.41565 | J17: ='Income Statement'!J9*Scenarios!J85/365 -> 215.17356 | K17: ='Income Statement'!K9*Scenarios!K85/365 -> 224.03324 | L17: ='Income Statement'!L9*Scenarios!L85/365 -> 234.04103
A18: Prepayments, deposits and other receivables | B18: US$m | C18: 34.929 | D18: 34.487 | E18: 37.34 | F18: 54.396 | G18: 39.018 | H18: ='Income Statement'!H9*Scenarios!H87 -> 50.626309 | I18: ='Income Statement'!I9*Scenarios!I87 -> 48.447727 | J18: ='Income Statement'!J9*Scenarios!J87 -> 48.618979 | K18: ='Income Statement'!K9*Scenarios!K87 -> 50.620843 | L18: ='Income Statement'!L9*Scenarios!L87 -> 52.882127
A19: Derivative financial instruments | B19: US$m | C19: 0.329 | D19: 5.116 | E19: 1.485 | F19: 2.288 | G19: 0.387 | H19: =G19 -> 0.387 | I19: =H19 -> 0.387 | J19: =I19 -> 0.387 | K19: =J19 -> 0.387 | L19: =K19 -> 0.387
A20: Financial assets at FVTPL | B20: US$m | C20: 32.105 | D20: 15.58 | E20: 14.78 | F20: 0.69 | G20: 167.386 | H20: =Scenarios!H93 -> 75 | I20: =Scenarios!I93 -> 75 | J20: =Scenarios!J93 -> 75 | K20: =Scenarios!K93 -> 75 | L20: =Scenarios!L93 -> 75
A21: Time deposits over three months | B21: US$m | C21: 225.217 | D21: 436.868 | E21: 294.113 | F21: 608.401 | G21: 537.644 | H21: =Scenarios!H92 -> 650 | I21: =Scenarios!I92 -> 650 | J21: =Scenarios!J92 -> 650 | K21: =Scenarios!K92 -> 650 | L21: =Scenarios!L92 -> 650 | M21: FY2021-23 split from "cash and bank balances" using cash equivalents in the cash flow statement
A22: Cash and cash equivalents | B22: US$m | C22: 694.264 | D22: 544.663 | E22: 122.21 | F22: 136.093 | G22: 243.584 | H22: ='Cash Flow'!H42 -> 222.24481 | I22: ='Cash Flow'!I42 -> 223.69716 | J22: ='Cash Flow'!J42 -> 186.13512 | K22: ='Cash Flow'!K42 -> 372.51296 | L22: ='Cash Flow'!L42 -> 582.96631
