Workbook

Sheet Cover
A1: SHEIN Global Holdings Ltd (0625.HK) - Cover
A2: Initiation of coverage - earnings and valuation model. Prepared 30-Sep-2026. Not investment advice.
A4: Recommendation
A5: Rating | C5: ='Valuation Summary'!C11 -> BUY
A6: 12-month price target (HK$) | C6: ='Valuation Summary'!C9 -> 45
A7: Share price (HK$, 30-Sep-2026) | C7: =Inputs!$C$5 -> 30.84
A8: Upside / (downside) | C8: ='Valuation Summary'!C10 -> 0.45914397
A9: Market cap, fully diluted (US$m) | C9: =Inputs!$C$20 -> 17372.748
A10: Pro forma unrestricted cash & investments (US$m) | C10: =Inputs!$C$30 -> 13485.398
A11: Active scenario | C11: =Scenarios!D4 -> Base
A12: Model integrity (Checks tab) | C12: =IF(Checks!C20,"ALL CHECKS PASS","CHECK ERRORS") -> ALL CHECKS PASS
A14: Tabs
A15: Inputs | C15: Market data, share count, pro forma cash bridge, WACC, price-target weights
A16: Scenarios | C16: Bull / Base / Bear drivers FY2027E-31E with live selector; scenario comparison
A17: Interim | C17: Quarterly / half-year actuals (1Q25-2Q26), 2H26E build, 30-Jun-2026 balance sheet
A18: Revenue Model | C18: Customers x frequency = orders; revenue by region, business model and category
A19: Income Statement | C19: IFRS P&L FY2023A-FY2031E, non-IFRS adjusted earnings, per-share data
A20: Balance Sheet | C20: Full balance sheet, equity roll-forward (IPO conversion), working-capital drivers
A21: Cash Flow | C21: Cash-flow statement in company presentation; free cash flow
A22: DCF Inputs | C22: Unlevered FCF build incl. 2H26E stub
A23: DCF | C23: WACC, discounting, terminal value, EV-to-equity bridge
A24: Sensitivity | C24: WACC x g, growth x margin, P/E x EPS tables
A25: Comps | C25: 11 listed peers with statistical summary and implied values
A26: Valuation Summary | C26: Price target, rating, football field, key financials
A27: Checks | C27: Balance, cash and tie-out checks
A29: Colour legend
A30: Blue | C30: Hard-coded historical data or assumption (change me)
A31: Black | C31: Formula / calculation
A32: Green | C32: Direct link to another tab
A34: Sources
A35: [1] | C35: SHEIN Global Holdings Ltd Global Offering prospectus, 24-Aug-2026 (HKEX: 2026082400019)
A36: [2] | C36: Announcement of final offer price and allotment results, 31-Aug-2026 (HKEX: 2026083102409)
A37: [3] | C37: Stabilising actions and lapse of over-allotment option, 27-Sep-2026 (HKEX: 2026092700013)
A38: [4] | C38: 2026 Interim Report, 28-Sep-2026 (HKEX: 2026092801831)
A39: [5] | C39: Market prices and peer multiples: stockanalysis.com, 29/30-Sep-2026 closes; FX approximate
A40: [6] | C40: All forecasts are analyst estimates; units US$m unless stated; fiscal year ends 31 December

Sheet Inputs
A1: SHEIN Global Holdings Ltd (0625.HK) - Inputs
A2: Market data, capital structure and valuation inputs. Blue = input.
A4: Market data (close of 30-Sep-2026)
A5: Share price | B5: HK$ | C5: 30.84 | D5: Close 30-Sep-2026 (stockanalysis.com / HKEX)
A6: HK$ per US$ | B6: HK$/US$ | C6: 7.845 | D6: HK$48.56 = US$6.19 per 2026 Interim Report note 28
A7: IPO offer price (1-Sep-2026 listing) | B7: HK$ | C7: 48.56 | D7: Allotment results announcement, 31-Aug-2026
A8: IPO indicative range - low | B8: HK$ | C8: 47.6 | D8: Prospectus cover
A9: IPO indicative range - high | B9: HK$ | C9: 49.5 | D9: Prospectus cover
A10: High since listing | B10: HK$ | C10: 48.56 | D10: 1-Sep-2026 open
A11: Low since listing | B11: HK$ | C11: 29.9 | D11: 30-Sep-2026 intraday low
A12: Valuation date | B12: date | C12: 46295
A13: Share count (m shares)
A14: Shares in issue at listing (Class A + Class B) | B14: m | C14: 4246.2026 | D14: Allotment results; over-allotment option lapsed 26-Sep-2026
A15: Pre-IPO ESOP options outstanding (near-nil strike) | B15: m | C15: 157.0826 | D15: 2026 Interim Report - Share Schemes
A16: Pre-IPO ESOP RSUs outstanding | B16: m | C16: 15.9497 | D16: 2026 Interim Report - Share Schemes
A17: Fully diluted shares | B17: m | C17: =C14+C15+C16 -> 4419.2349 | D17: Treasury method ~ full count given near-nil strikes
A18: Annual dilution from post-IPO share scheme | B18: % | C18: 0.005 | D18: Analyst assumption
A19: Market cap (fully diluted) | B19: HK$m | C19: =C5*C17 -> 136289.2
A20: Market cap (fully diluted) | B20: US$m | C20: =C19/C6 -> 17372.748
A21: Pro forma cash bridge at listing (US$m)
A22: Cash resources, 30-Jun-2026 (cash, restricted, ST inv.) | B22: US$m | C22: =Interim!I87 -> 15248 | D22: 2026 Interim Report
A23: Less: restricted cash (current + non-current) | B23: US$m | C23: =Interim!I64+Interim!I65 -> 660
A24: IPO net proceeds | B24: HK$m | C24: 13214.1 | D24: Allotment results announcement
A25: IPO net proceeds | B25: US$m | C25: =C24/C6 -> 1684.3977
A26: Conversion Adjustment cash paid to Series Pre-D/D/D+ holders | B26: US$m | C26: 2200 | D26: Interim Report note 15 (paid at listing)
A27: 8% p.a. distribution to preferred holders (total, 2026) | B27: US$m | C27: 1082 | D27: US$725m paid 1H26 + US$357m in 2H26
A28: of which unpaid at 30-Jun-2026 | B28: US$m | C28: 357 | D28: Accrued at 30-Jun-2026
A29: 12% p.a. distribution (5-Mar-2026 to listing) | B29: US$m | C29: 230 | D29: Prospectus: est. US$230.4m; paid Sep-2026
A30: Pro forma unrestricted cash & investments | B30: US$m | C30: =C22-C23+C25-C26-C28-C29 -> 13485.398
A31: Less: minimum operating cash (analyst) | B31: US$m | C31: 1500 | D31: ~3.5% of revenue; supports negative working-capital model
A32: Less: regulatory contingency reserve (analyst) | B32: US$m | C32: 1000 | D32: EU DSA, FTC, CNIL appeal, Irish DPC exposure
A33: Plus: associates & FVTPL investments (book) | B33: US$m | C33: =Interim!I73+Interim!I74 -> 411
A34: Memo: lease liabilities (not deducted; lease cost in FCFF) | B34: US$m | C34: =Interim!I83 -> 1145
A35: Net cash used in valuation | B35: US$m | C35: =C30-C31-C32+C33 -> 11396.398
A36: Preferred-share conversion at listing (1-Sep-2026)
A37: Ordinary shares in issue before IPO (post 1:50 split) | B37: m | C37: 2568.5058 | D37: 51,370,116 pre-split (Interim Report note 14)
A38: New Class B shares issued in the Global Offering | B38: m | C38: 279.9925 | D38: Allotment results
A39: Class B shares issued on conversion (incl. 19.6m adjustment shares) | B39: m | C39: =C14-C37-C38 -> 1397.7043
A40: Carrying value of preferred shares, 30-Jun-2026 | B40: US$m | C40: =Interim!I82 -> 15105 | D40: Interim Report
A41: Fair value at conversion: shares at IPO price + cash compensation + 12% distribution | B41: US$m | C41: =C39*C7/C6+C26+C29 -> 11081.692
...

Sheet Scenarios
A1: SHEIN Global Holdings Ltd (0625.HK) - Scenarios
A2: Operating drivers by scenario for FY2027E-FY2031E. Change C4 to switch the whole model.
A4: Active scenario (1 = Bull, 2 = Base, 3 = Bear) | C4: 2 | D4: =CHOOSE(C4,"Bull","Base","Bear") -> Base
B6: Case | C6: FY2027E | D6: FY2028E | E6: FY2029E | F6: FY2030E | G6: FY2031E
A7: US net revenue growth (YoY)
B8: Bull | C8: 0.05 | D8: 0.06 | E8: 0.06 | F8: 0.05 | G8: 0.05
B9: Base | C9: 0.02 | D9: 0.04 | E9: 0.04 | F9: 0.04 | G9: 0.035
B10: Bear | C10: -0.04 | D10: 0 | E10: 0.02 | F10: 0.02 | G10: 0.02
B11: Selected | C11: =CHOOSE($C$4,C8,C9,C10) -> 0.02 | D11: =CHOOSE($C$4,D8,D9,D10) -> 0.04 | E11: =CHOOSE($C$4,E8,E9,E10) -> 0.04 | F11: =CHOOSE($C$4,F8,F9,F10) -> 0.04 | G11: =CHOOSE($C$4,G8,G9,G10) -> 0.035 | H11: Base: 1H26 -9.9%; de minimis base effect fades 2027; Everlane consolidated
A12: Europe net revenue growth (YoY)
B13: Bull | C13: 0.02 | D13: 0.07 | E13: 0.07 | F13: 0.06 | G13: 0.06
B14: Base | C14: -0.04 | D14: 0.04 | E14: 0.05 | F14: 0.05 | G14: 0.045
B15: Bear | C15: -0.1 | D15: -0.02 | E15: 0.02 | F15: 0.03 | G15: 0.03
B16: Selected | C16: =CHOOSE($C$4,C13,C14,C15) -> -0.04 | D16: =CHOOSE($C$4,D13,D14,D15) -> 0.04 | E16: =CHOOSE($C$4,E13,E14,E15) -> 0.05 | F16: =CHOOSE($C$4,F13,F14,F15) -> 0.05 | G16: =CHOOSE($C$4,G13,G14,G15) -> 0.045 | H16: EUR 3/item duty from 1-Jul-2026 + handling fee; 2Q26 -13.9%; 1H27 laps pre-duty base
A17: Rest of world net revenue growth (YoY)
B18: Bull | C18: 0.16 | D18: 0.13 | E18: 0.11 | F18: 0.1 | G18: 0.09
B19: Base | C19: 0.12 | D19: 0.1 | E19: 0.09 | F19: 0.08 | G19: 0.07
B20: Bear | C20: 0.08 | D20: 0.07 | E20: 0.06 | F20: 0.05 | G20: 0.04
B21: Selected | C21: =CHOOSE($C$4,C18,C19,C20) -> 0.12 | D21: =CHOOSE($C$4,D18,D19,D20) -> 0.1 | E21: =CHOOSE($C$4,E18,E19,E20) -> 0.09 | F21: =CHOOSE($C$4,F18,F19,F20) -> 0.08 | G21: =CHOOSE($C$4,G18,G19,G20) -> 0.07 | H21: 2Q26 +21.6% (LatAm-led) despite Middle East drag
A22: Service (marketplace) revenue % of net revenues
B23: Bull | C23: 0.145 | D23: 0.15 | E23: 0.155 | F23: 0.16 | G23: 0.163
B24: Base | C24: 0.145 | D24: 0.15 | E24: 0.155 | F24: 0.16 | G24: 0.163
B25: Bear | C25: 0.145 | D25: 0.15 | E25: 0.155 | F25: 0.16 | G25: 0.163
B26: Selected | C26: =CHOOSE($C$4,C23,C24,C25) -> 0.145 | D26: =CHOOSE($C$4,D23,D24,D25) -> 0.15 | E26: =CHOOSE($C$4,E23,E24,E25) -> 0.155 | F26: =CHOOSE($C$4,F23,F24,F25) -> 0.16 | G26: =CHOOSE($C$4,G23,G24,G25) -> 0.163 | H26: Mgmt: 1P remains core; marketplace mix 13.4% in 1H26
A27: Cost of sales % of product revenue
B28: Bull | C28: 0.34 | D28: 0.338 | E28: 0.336 | F28: 0.335 | G28: 0.335
B29: Base | C29: 0.343 | D29: 0.342 | E29: 0.341 | F29: 0.34 | G29: 0.34
B30: Bear | C30: 0.346 | D30: 0.346 | E30: 0.346 | F30: 0.346 | G30: 0.346
B31: Selected | C31: =CHOOSE($C$4,C28,C29,C30) -> 0.343 | D31: =CHOOSE($C$4,D28,D29,D30) -> 0.342 | E31: =CHOOSE($C$4,E28,E29,E30) -> 0.341 | F31: =CHOOSE($C$4,F28,F29,F30) -> 0.34 | G31: =CHOOSE($C$4,G28,G29,G30) -> 0.34 | H31: 1H26 34.6%; FY25 36.2%; higher price-point brands a partial offset
A32: Fulfilment expenses % of net revenues
B33: Bull | C33: 0.498 | D33: 0.495 | E33: 0.493 | F33: 0.493 | G33: 0.493
B34: Base | C34: 0.505 | D34: 0.502 | E34: 0.5 | F34: 0.5 | G34: 0.5
B35: Bear | C35: 0.512 | D35: 0.51 | E35: 0.508 | F35: 0.508 | G35: 0.508
B36: Selected | C36: =CHOOSE($C$4,C33,C34,C35) -> 0.505 | D36: =CHOOSE($C$4,D33,D34,D35) -> 0.502 | E36: =CHOOSE($C$4,E33,E34,E35) -> 0.5 | F36: =CHOOSE($C$4,F33,F34,F35) -> 0.5 | G36: =CHOOSE($C$4,G33,G34,G35) -> 0.5 | H36: Duties booked in fulfilment; freight normalises; local inventory adds cost near term
A37: Marketing expenses % of net revenues
B38: Bull | C38: 0.133 | D38: 0.13 | E38: 0.128 | F38: 0.128 | G38: 0.128
B39: Base | C39: 0.135 | D39: 0.133 | E39: 0.132 | F39: 0.132 | G39: 0.132
B40: Bear | C40: 0.138 | D40: 0.138 | E40: 0.136 | F40: 0.136 | G40: 0.136
B41: Selected | C41: =CHOOSE($C$4,C38,C39,C40) -> 0.135 | D41: =CHOOSE($C$4,D38,D39,D40) -> 0.133 | E41: =CHOOSE($C$4,E38,E39,E40) -> 0.132 | F41: =CHOOSE($C$4,F38,F39,F40) -> 0.132 | G41: =CHOOSE($C$4,G38,G39,G40) -> 0.132 | H41: FY25 14.8%; 1H26 14.6%; IPO proceeds 40% earmarked for brand
A42: Technology & content % of net revenues
...

Sheet Interim
A1: SHEIN Global Holdings Ltd (0625.HK) - Interim
A2: Quarterly and half-year actuals (unaudited except FY/3M audited), 2H26E build, balance sheet at 30-Jun-2026.
A4: US$m unless stated | B4: 1Q25A | C4: 2Q25A | D4: 1H25A | E4: 2H25A | F4: FY2025A | G4: 1Q26A | H4: 2Q26A | I4: 1H26A | J4: 2H26E | K4: FY2026E | L4: 2H26E driver
A5: Net revenues by region (US$m)
A6: United States | B6: 2380 | C6: 2632 | D6: =B6+C6 -> 5012 | E6: =F6-D6 -> 5089 | F6: ='Revenue Model'!E15 -> 10101 | G6: 2040 | H6: 2474 | I6: =G6+H6 -> 4514 | J6: =E6*(1+L6) -> 4681.88 | K6: =I6+J6 -> 9195.88 | L6: -0.08 | M6: 2H26E: 2Q26 -6.0%; early-3Q US sales >10% lower (Jefferies)
A7: Europe | B7: 2843 | C7: 4379 | D7: =B7+C7 -> 7222 | E7: =F7-D7 -> 7580 | F7: ='Revenue Model'!E18 -> 14802 | G7: 2908 | H7: 3770 | I7: =G7+H7 -> 6678 | J7: =E7*(1+L7) -> 6443 | K7: =I7+J7 -> 13121 | L7: -0.15 | M7: 2H26E: EUR 150 exemption removed 1-Jul-2026; price rises + lower ad spend
A8: Rest of world | B8: 3729 | C8: 3977 | D8: =B8+C8 -> 7706 | E8: =F8-D8 -> 9238 | F8: ='Revenue Model'!E21 -> 16944 | G8: 4104 | H8: 4838 | I8: =G8+H8 -> 8942 | J8: =E8*(1+L8) -> 10623.7 | K8: =I8+J8 -> 19565.7 | L8: 0.15 | M8: 2H26E: LatAm strength; Middle East still soft
A9: Total net revenues | B9: =B6+B7+B8 -> 8952 | C9: =C6+C7+C8 -> 10988 | D9: =D6+D7+D8 -> 19940 | E9: =E6+E7+E8 -> 21907 | F9: =F6+F7+F8 -> 41847 | G9: =G6+G7+G8 -> 9052 | H9: =H6+H7+H8 -> 11082 | I9: =I6+I7+I8 -> 20134 | ... K9: =K6+K7+K8 -> 41882.58
A10: US YoY | G10: =IFERROR(G6/B6-1,0) -> -0.14285714 | H10: =IFERROR(H6/C6-1,0) -> -0.060030395 | I10: =IFERROR(I6/D6-1,0) -> -0.099361532 | J10: =IFERROR(J6/E6-1,0) -> -0.08 | K10: =IFERROR(K6/F6-1,0) -> -0.08960697
A11: Europe YoY | G11: =IFERROR(G7/B7-1,0) -> 0.022863173 | H11: =IFERROR(H7/C7-1,0) -> -0.13907285 | I11: =IFERROR(I7/D7-1,0) -> -0.075325395 | J11: =IFERROR(J7/E7-1,0) -> -0.15 | K11: =IFERROR(K7/F7-1,0) -> -0.11356573
A12: Rest of world YoY | G12: =IFERROR(G8/B8-1,0) -> 0.10056315 | H12: =IFERROR(H8/C8-1,0) -> 0.21649485 | I12: =IFERROR(I8/D8-1,0) -> 0.1603945 | J12: =IFERROR(J8/E8-1,0) -> 0.15 | K12: =IFERROR(K8/F8-1,0) -> 0.15472734
A13: Total YoY | G13: =IFERROR(G9/B9-1,0) -> 0.011170688 | H13: =IFERROR(H9/C9-1,0) -> 0.008554787 | I13: =IFERROR(I9/D9-1,0) -> 0.0097291876 | J13: =IFERROR(J9/E9-1,0) -> -0.0072314785 | K13: =IFERROR(K9/F9-1,0) -> 0.00085024016
A14: Net revenues by type (US$m)
A15: Product revenues (first-party) | B15: 7765 | C15: 10013 | D15: =B15+C15 -> 17778 | E15: =F15-D15 -> 19329 | F15: ='Revenue Model'!E32 -> 37107 | G15: 7757 | H15: 9676 | I15: =G15+H15 -> 17433 | J15: =J9-J16 -> 18812.522 | K15: =I15+J15 -> 36245.522
A16: Service revenues (marketplace & brand enablement) | B16: 1187 | C16: 975 | D16: =B16+C16 -> 2162 | E16: =F16-D16 -> 2578 | F16: ='Revenue Model'!E30 -> 4740 | G16: 1295 | H16: 1406 | I16: =G16+H16 -> 2701 | J16: =J9*L17 -> 2936.0583 | K16: =I16+J16 -> 5637.0583
A17: Service % of net revenues | B17: =IFERROR(B16/B9,0) -> 0.13259607 | C17: =IFERROR(C16/C9,0) -> 0.088733163 | D17: =IFERROR(D16/D9,0) -> 0.10842528 | E17: =IFERROR(E16/E9,0) -> 0.11767928 | F17: =IFERROR(F16/F9,0) -> 0.11326977 | G17: =IFERROR(G16/G9,0) -> 0.14306231 | H17: =IFERROR(H16/H9,0) -> 0.12687241 | I17: =IFERROR(I16/I9,0) -> 0.13415119 | ... K17: =IFERROR(K16/K9,0) -> 0.13459195 | L17: 0.135
A18: Product revenues YoY | G18: =IFERROR(G15/B15-1,0) -> -0.001030264 | H18: =IFERROR(H15/C15-1,0) -> -0.033656247 | I18: =IFERROR(I15/D15-1,0) -> -0.019406007 | J18: =IFERROR(J15/E15-1,0) -> -0.026720384 | K18: =IFERROR(K15/F15-1,0) -> -0.023216059
A19: Service revenues YoY | G19: =IFERROR(G16/B16-1,0) -> 0.090985678 | H19: =IFERROR(H16/C16-1,0) -> 0.44205128 | I19: =IFERROR(I16/D16-1,0) -> 0.2493062 | J19: =IFERROR(J16/E16-1,0) -> 0.13888995 | K19: =IFERROR(K16/F16-1,0) -> 0.18925281
A20: Operating KPIs
A21: Total orders (m) | B21: 240 | C21: 277 | D21: =B21+C21 -> 517 | E21: =F21-D21 -> 561 | F21: ='Revenue Model'!E9 -> 1078 | G21: 251 | H21: 298 | I21: =G21+H21 -> 549 | J21: =E21*(1+L22) -> 594.66 | K21: =I21+J21 -> 1143.66
A22: Orders YoY | G22: =IFERROR(G21/B21-1,0) -> 0.045833333 | H22: =IFERROR(H21/C21-1,0) -> 0.075812274 | I22: =IFERROR(I21/D21-1,0) -> 0.061895551 | J22: =IFERROR(J21/E21-1,0) -> 0.06 | K22: =IFERROR(K21/F21-1,0) -> 0.060909091 | L22: 0.06 | M22: 1H26 +6.4%, 2Q26 +7.6%
A23: Net revenue per order (US$) | B23: =IFERROR(B9/B21,0) -> 37.3 | C23: =IFERROR(C9/C21,0) -> 39.66787 | D23: =IFERROR(D9/D21,0) -> 38.568665 | E23: =IFERROR(E9/E21,0) -> 39.049911 | F23: =IFERROR(F9/F21,0) -> 38.819109 | G23: =IFERROR(G9/G21,0) -> 36.063745 | H23: =IFERROR(H9/H21,0) -> 37.187919 | I23: =IFERROR(I9/I21,0) -> 36.673953 | ... K23: =IFERROR(K9/K21,0) -> 36.621531
A24: Active customers, trailing 12 months (m) | B24: 241 | C24: 254 | F24: 273 | G24: 281 | H24: 291 | I24: 291
A25: Income statement (US$m)
A26: Cost of sales | B26: 3339 | C26: 3628 | D26: =B26+C26 -> 6967 | E26: =F26-D26 -> 6466 | F26: ='Income Statement'!E11 -> 13433 | G26: 2679 | H26: 3347 | I26: =G26+H26 -> 6026 | J26: =J15*L27 -> 6396.2574 | K26: =I26+J26 -> 12422.257
A27: % of product revenues | B27: =IFERROR(B26/B15,0) -> 0.43000644 | C27: =IFERROR(C26/C15,0) -> 0.36232897 | D27: =IFERROR(D26/D15,0) -> 0.39188885 | E27: =IFERROR(E26/E15,0) -> 0.33452326 | F27: =IFERROR(F26/F15,0) -> 0.36200717 | G27: =IFERROR(G26/G15,0) -> 0.34536548 | H27: =IFERROR(H26/H15,0) -> 0.3459074 | I27: =IFERROR(I26/I15,0) -> 0.34566627 | ... K27: =IFERROR(K26/K15,0) -> 0.3427253 | L27: 0.34
A28: Gross profit | B28: =B9-B26 -> 5613 | C28: =C9-C26 -> 7360 | D28: =D9-D26 -> 12973 | E28: =E9-E26 -> 15441 | F28: =F9-F26 -> 28414 | G28: =G9-G26 -> 6373 | H28: =H9-H26 -> 7735 | I28: =I9-I26 -> 14108 | ... K28: =K9-K26 -> 29460.323
A29: Gross margin | B29: =IFERROR(B28/B9,0) -> 0.62701072 | C29: =IFERROR(C28/C9,0) -> 0.66982162 | D29: =IFERROR(D28/D9,0) -> 0.65060181 | E29: =IFERROR(E28/E9,0) -> 0.7048432 | F29: =IFERROR(F28/F9,0) -> 0.6789973 | G29: =IFERROR(G28/G9,0) -> 0.70404331 | H29: =IFERROR(H28/H9,0) -> 0.6979787 | I29: =IFERROR(I28/I9,0) -> 0.70070527 | ... K29: =IFERROR(K28/K9,0) -> 0.70340277
A30: Fulfilment expenses | B30: 3831 | C30: 4730 | D30: =B30+C30 -> 8561 | E30: =F30-D30 -> 10511 | F30: ='Income Statement'!E16 -> 19072 | G30: 4322 | H30: 5587 | I30: =G30+H30 -> 9909 | J30: =J9*L31 -> 11091.776 | K30: =I30+J30 -> 21000.776
A31: % of net revenues | B31: =IFERROR(B30/B9,0) -> 0.42794906 | C31: =IFERROR(C30/C9,0) -> 0.4304696 | D31: =IFERROR(D30/D9,0) -> 0.42933801 | E31: =IFERROR(E30/E9,0) -> 0.47980098 | F31: =IFERROR(F30/F9,0) -> 0.45575549 | G31: =IFERROR(G30/G9,0) -> 0.47746354 | H31: =IFERROR(H30/H9,0) -> 0.50415088 | I31: =IFERROR(I30/I9,0) -> 0.49215258 | ... K31: =IFERROR(K30/K9,0) -> 0.5014203 | L31: 0.51
A32: per order (US$) | B32: =IFERROR(B30/B21,0) -> 15.9625 | C32: =IFERROR(C30/C21,0) -> 17.075812 | D32: =IFERROR(D30/D21,0) -> 16.558994 | E32: =IFERROR(E30/E21,0) -> 18.736185 | F32: =IFERROR(F30/F21,0) -> 17.692022 | G32: =IFERROR(G30/G21,0) -> 17.219124 | H32: =IFERROR(H30/H21,0) -> 18.748322 | I32: =IFERROR(I30/I21,0) -> 18.04918 | ... K32: =IFERROR(K30/K21,0) -> 18.362779
A33: Marketing expenses | B33: 1088 | C33: 1576 | D33: =B33+C33 -> 2664 | E33: =F33-D33 -> 3527 | F33: ='Income Statement'!E21 -> 6191 | G33: 1430 | H33: 1511 | I33: =G33+H33 -> 2941 | J33: =J9*L34 -> 2936.0583 | K33: =I33+J33 -> 5877.0583
A34: % of net revenues | B34: =IFERROR(B33/B9,0) -> 0.12153709 | C34: =IFERROR(C33/C9,0) -> 0.1434292 | D34: =IFERROR(D33/D9,0) -> 0.1336008 | E34: =IFERROR(E33/E9,0) -> 0.16099877 | F34: =IFERROR(F33/F9,0) -> 0.1479437 | G34: =IFERROR(G33/G9,0) -> 0.15797614 | H34: =IFERROR(H33/H9,0) -> 0.13634723 | I34: =IFERROR(I33/I9,0) -> 0.14607132 | ... K34: =IFERROR(K33/K9,0) -> 0.14032226 | L34: 0.135
A35: Technology & content | B35: 220 | C35: 221 | D35: =B35+C35 -> 441 | E35: =F35-D35 -> 455 | F35: ='Income Statement'!E23 -> 896 | G35: 241 | H35: 258 | I35: =G35+H35 -> 499 | J35: =J9*L36 -> 500.21734 | K35: =I35+J35 -> 999.21734
A36: % of net revenues | B36: =IFERROR(B35/B9,0) -> 0.024575514 | C36: =IFERROR(C35/C9,0) -> 0.02011285 | D36: =IFERROR(D35/D9,0) -> 0.022116349 | E36: =IFERROR(E35/E9,0) -> 0.020769617 | F36: =IFERROR(F35/F9,0) -> 0.021411332 | G36: =IFERROR(G35/G9,0) -> 0.026623951 | H36: =IFERROR(H35/H9,0) -> 0.023280996 | I36: =IFERROR(I35/I9,0) -> 0.024783948 | ... K36: =IFERROR(K35/K9,0) -> 0.023857588 | L36: 0.023
A37: General & administrative | B37: 126 | C37: 135 | D37: =B37+C37 -> 261 | E37: =F37-D37 -> 287 | F37: ='Income Statement'!E25 -> 548 | G37: 122 | H37: 144 | I37: =G37+H37 -> 266 | J37: =J9*L38 -> 282.73154 | K37: =I37+J37 -> 548.73154
A38: % of net revenues | B38: =IFERROR(B37/B9,0) -> 0.014075067 | C38: =IFERROR(C37/C9,0) -> 0.01228613 | D38: =IFERROR(D37/D9,0) -> 0.013089268 | E38: =IFERROR(E37/E9,0) -> 0.013100835 | F38: =IFERROR(F37/F9,0) -> 0.013095323 | G38: =IFERROR(G37/G9,0) -> 0.013477684 | H38: =IFERROR(H37/H9,0) -> 0.012994044 | I38: =IFERROR(I37/I9,0) -> 0.013211483 | ... K38: =IFERROR(K37/K9,0) -> 0.013101665 | L38: 0.013
A39: Operating income | B39: =B28-B30-B33-B35-B37 -> 348 | C39: =C28-C30-C33-C35-C37 -> 698 | D39: =D28-D30-D33-D35-D37 -> 1046 | E39: =E28-E30-E33-E35-E37 -> 661 | F39: =F28-F30-F33-F35-F37 -> 1707 | G39: =G28-G30-G33-G35-G37 -> 258 | H39: =H28-H30-H33-H35-H37 -> 235 | I39: =I28-I30-I33-I35-I37 -> 493 | ... K39: =K28-K30-K33-K35-K37 -> 1034.5396
A40: Operating margin | B40: =IFERROR(B39/B9,0) -> 0.038873995 | C40: =IFERROR(C39/C9,0) -> 0.063523844 | D40: =IFERROR(D39/D9,0) -> 0.052457372 | E40: =IFERROR(E39/E9,0) -> 0.030173004 | F40: =IFERROR(F39/F9,0) -> 0.040791455 | G40: =IFERROR(G39/G9,0) -> 0.028501989 | H40: =IFERROR(H39/H9,0) -> 0.021205559 | I40: =IFERROR(I39/I9,0) -> 0.024485944 | ... K40: =IFERROR(K39/K9,0) -> 0.024700953
A41: Share-based compensation (in opex) | B41: 22 | C41: 17 | D41: =B41+C41 -> 39 | E41: =F41-D41 -> 46 | F41: ='Income Statement'!E32 -> 85 | G41: 26 | H41: 19 | I41: =G41+H41 -> 45 | J41: =L41 -> 45 | K41: =I41+J41 -> 90 | L41: 45
...

Sheet Revenue Model
A1: SHEIN Global Holdings Ltd (0625.HK) - Revenue Model
A2: Revenue build: customers x order frequency; revenue by region, business model and category.
A4: US$m unless stated | C4: FY2023A | D4: FY2024A | E4: FY2025A | F4: FY2026E | G4: FY2027E | H4: FY2028E | I4: FY2029E | J4: FY2030E | K4: FY2031E
A5: Customer & order KPIs
A6: Active customers (m) | C6: 186 | D6: 230 | E6: 273 | F6: 300 | G6: =F6*(1+G7) -> 318 | H6: =G6*(1+H7) -> 333.9 | I6: =H6*(1+I7) -> 347.256 | J6: =I6*(1+J7) -> 361.14624 | K6: =J6*(1+K7) -> 373.78636 | M6: FY26E: LTM Jun-26 already 291m
A7: YoY growth | D7: =IFERROR(D6/C6-1,0) -> 0.23655914 | E7: =IFERROR(E6/D6-1,0) -> 0.18695652 | F7: =IFERROR(F6/E6-1,0) -> 0.098901099 | G7: =Scenarios!C56 -> 0.06 | H7: =Scenarios!D56 -> 0.05 | I7: =Scenarios!E56 -> 0.04 | J7: =Scenarios!F56 -> 0.04 | K7: =Scenarios!G56 -> 0.035
A8: Orders per active customer (x) | C8: =C9/C6 -> 3.844086 | D8: =D9/D6 -> 3.9956522 | E8: =E9/E6 -> 3.9487179 | F8: =F9/F6 -> 3.8122 | G8: =Scenarios!C61 -> 3.85 | H8: =Scenarios!D61 -> 3.9 | I8: =Scenarios!E61 -> 3.95 | J8: =Scenarios!F61 -> 4 | K8: =Scenarios!G61 -> 4
A9: Total orders (m) | C9: 715 | D9: 919 | E9: 1078 | F9: =Interim!K21 -> 1143.66 | G9: =G6*G8 -> 1224.3 | H9: =H6*H8 -> 1302.21 | I9: =I6*I8 -> 1371.6612 | J9: =J6*J8 -> 1444.585 | K9: =K6*K8 -> 1495.1454
A10: YoY growth | D10: =IFERROR(D9/C9-1,0) -> 0.28531469 | E10: =IFERROR(E9/D9-1,0) -> 0.17301415 | F10: =IFERROR(F9/E9-1,0) -> 0.060909091 | G10: =IFERROR(G9/F9-1,0) -> 0.070510466 | H10: =IFERROR(H9/G9-1,0) -> 0.063636364 | I10: =IFERROR(I9/H9-1,0) -> 0.053333333 | J10: =IFERROR(J9/I9-1,0) -> 0.053164557 | K10: =IFERROR(K9/J9-1,0) -> 0.035
A11: Net revenue per order (US$) | C11: =C24/C9 -> 44.899301 | D11: =D24/D9 -> 42.163221 | E11: =E24/E9 -> 38.819109 | F11: =F24/F9 -> 36.621531 | G11: =G24/G9 -> 35.848682 | H11: =H24/H9 -> 36.061725 | I11: =I24/I9 -> 36.579429 | J11: =J24/J9 -> 36.944931 | K11: =K24/K9 -> 37.705793
A12: YoY growth | D12: =IFERROR(D11/C11-1,0) -> -0.060938139 | E12: =IFERROR(E11/D11-1,0) -> -0.079313472 | F12: =IFERROR(F11/E11-1,0) -> -0.056610742 | G12: =IFERROR(G11/F11-1,0) -> -0.02110367 | H12: =IFERROR(H11/G11-1,0) -> 0.0059428223 | I12: =IFERROR(I11/H11-1,0) -> 0.014356056 | J12: =IFERROR(J11/I11-1,0) -> 0.0099920229 | K12: =IFERROR(K11/J11-1,0) -> 0.020594491 | M12: Diluted by marketplace mix (service revenue = take rate only)
A13: Net revenue per active customer (US$) | C13: =C24/C6 -> 172.59677 | D13: =D24/D6 -> 168.46957 | E13: =E24/E6 -> 153.28571 | F13: =F24/F6 -> 139.6086 | G13: =G24/G6 -> 138.01743 | H13: =H24/H6 -> 140.64073 | I13: =I24/I6 -> 144.48874 | J13: =J24/J6 -> 147.77972 | K13: =K24/K6 -> 150.82317
A14: Net revenues by geography (US$m)
A15: United States | C15: 9454 | D15: 10464 | E15: 10101 | F15: =Interim!K6 -> 9195.88 | G15: =F15*(1+G16) -> 9379.7976 | H15: =G15*(1+H16) -> 9754.9895 | I15: =H15*(1+I16) -> 10145.189 | J15: =I15*(1+J16) -> 10550.997 | K15: =J15*(1+K16) -> 10920.282
A16: YoY growth | D16: =IFERROR(D15/C15-1,0) -> 0.10683309 | E16: =IFERROR(E15/D15-1,0) -> -0.034690367 | F16: =IFERROR(F15/E15-1,0) -> -0.08960697 | G16: =Scenarios!C11 -> 0.02 | H16: =Scenarios!D11 -> 0.04 | I16: =Scenarios!E11 -> 0.04 | J16: =Scenarios!F11 -> 0.04 | K16: =Scenarios!G11 -> 0.035
A17: % of net revenues | C17: =IFERROR(C15/C24,0) -> 0.29448961 | D17: =IFERROR(D15/D24,0) -> 0.27005265 | E17: =IFERROR(E15/E24,0) -> 0.24137931 | F17: =IFERROR(F15/F24,0) -> 0.21956336 | G17: =IFERROR(G15/G24,0) -> 0.21371373 | H17: =IFERROR(H15/H24,0) -> 0.20773003 | I17: =IFERROR(I15/I24,0) -> 0.20219778 | J17: =IFERROR(J15/J24,0) -> 0.19769493 | K17: =IFERROR(K15/K24,0) -> 0.19370566
A18: Europe | C18: 10214 | D18: 13603 | E18: 14802 | F18: =Interim!K7 -> 13121 | G18: =F18*(1+G19) -> 12596.16 | H18: =G18*(1+H19) -> 13100.006 | I18: =H18*(1+I19) -> 13755.007 | J18: =I18*(1+J19) -> 14442.757 | K18: =J18*(1+K19) -> 15092.681
A19: YoY growth | D19: =IFERROR(D18/C18-1,0) -> 0.33179949 | E19: =IFERROR(E18/D18-1,0) -> 0.088142322 | F19: =IFERROR(F18/E18-1,0) -> -0.11356573 | G19: =Scenarios!C16 -> -0.04 | H19: =Scenarios!D16 -> 0.04 | I19: =Scenarios!E16 -> 0.05 | J19: =Scenarios!F16 -> 0.05 | K19: =Scenarios!G16 -> 0.045
A20: % of net revenues | C20: =IFERROR(C18/C24,0) -> 0.31816341 | D20: =IFERROR(D18/D24,0) -> 0.35106328 | E20: =IFERROR(E18/E24,0) -> 0.35371711 | F20: =IFERROR(F18/F24,0) -> 0.3132806 | G20: =IFERROR(G18/G24,0) -> 0.28699685 | H20: =IFERROR(H18/H24,0) -> 0.27896132 | I20: =IFERROR(I18/I24,0) -> 0.27414292 | J20: =IFERROR(J18/J24,0) -> 0.27061518 | K20: =IFERROR(K18/K24,0) -> 0.26771634
A21: Rest of world (LatAm, Middle East, APAC & other) | C21: 12435 | D21: 14681 | E21: 16944 | F21: =Interim!K8 -> 19565.7 | G21: =F21*(1+G22) -> 21913.584 | H21: =G21*(1+H22) -> 24104.942 | I21: =H21*(1+I22) -> 26274.387 | J21: =I21*(1+J22) -> 28376.338 | K21: =J21*(1+K22) -> 30362.682
A22: YoY growth | D22: =IFERROR(D21/C21-1,0) -> 0.18061922 | E22: =IFERROR(E21/D21-1,0) -> 0.15414481 | F22: =IFERROR(F21/E21-1,0) -> 0.15472734 | G22: =Scenarios!C21 -> 0.12 | H22: =Scenarios!D21 -> 0.1 | I22: =Scenarios!E21 -> 0.09 | J22: =Scenarios!F21 -> 0.08 | K22: =Scenarios!G21 -> 0.07
A23: % of net revenues | C23: =IFERROR(C21/C24,0) -> 0.38734698 | D23: =IFERROR(D21/D24,0) -> 0.37888407 | E23: =IFERROR(E21/E24,0) -> 0.40490358 | F23: =IFERROR(F21/F24,0) -> 0.46715603 | G23: =IFERROR(G21/G24,0) -> 0.49928943 | H23: =IFERROR(H21/H24,0) -> 0.51330865 | I23: =IFERROR(I21/I24,0) -> 0.5236593 | J23: =IFERROR(J21/J24,0) -> 0.53168989 | K23: =IFERROR(K21/K24,0) -> 0.538578
A24: Total net revenues | C24: =C15+C18+C21 -> 32103 | D24: =D15+D18+D21 -> 38748 | E24: =E15+E18+E21 -> 41847 | F24: =F15+F18+F21 -> 41882.58 | G24: =G15+G18+G21 -> 43889.542 | H24: =H15+H18+H21 -> 46959.938 | I24: =I15+I18+I21 -> 50174.583 | J24: =J15+J18+J21 -> 53370.092 | K24: =K15+K18+K21 -> 56375.645
A25: YoY growth | D25: =IFERROR(D24/C24-1,0) -> 0.20699 | E25: =IFERROR(E24/D24-1,0) -> 0.079978321 | F25: =IFERROR(F24/E24-1,0) -> 0.00085024016 | G25: =IFERROR(G24/F24-1,0) -> 0.047918767 | H25: =IFERROR(H24/G24-1,0) -> 0.069957366 | I25: =IFERROR(I24/H24-1,0) -> 0.068455046 | J25: =IFERROR(J24/I24-1,0) -> 0.063687801 | K25: =IFERROR(K24/J24-1,0) -> 0.056315298
A26: Memo: net revenues outside the US | C26: =C18+C21 -> 22649 | D26: =D18+D21 -> 28284 | E26: =E18+E21 -> 31746 | F26: =F18+F21 -> 32686.7 | G26: =G18+G21 -> 34509.744 | H26: =H18+H21 -> 37204.949 | I26: =I18+I21 -> 40029.394 | J26: =J18+J21 -> 42819.095 | K26: =K18+K21 -> 45455.363
A27: YoY growth | D27: =IFERROR(D26/C26-1,0) -> 0.24879686 | E27: =IFERROR(E26/D26-1,0) -> 0.12240136 | F27: =IFERROR(F26/E26-1,0) -> 0.02963208 | G27: =IFERROR(G26/F26-1,0) -> 0.055773266 | H27: =IFERROR(H26/G26-1,0) -> 0.07809982 | I27: =IFERROR(I26/H26-1,0) -> 0.075915845 | J27: =IFERROR(J26/I26-1,0) -> 0.06969132 | K27: =IFERROR(K26/J26-1,0) -> 0.061567572
A28: Net revenues by business model (US$m)
A29: Service revenues % of total | C29: =IFERROR(C30/C24,0) -> 0.027037972 | D29: =IFERROR(D30/D24,0) -> 0.087669041 | E29: =IFERROR(E30/E24,0) -> 0.11326977 | F29: =IFERROR(F30/F24,0) -> 0.13459195 | G29: =Scenarios!C26 -> 0.145 | H29: =Scenarios!D26 -> 0.15 | I29: =Scenarios!E26 -> 0.155 | J29: =Scenarios!F26 -> 0.16 | K29: =Scenarios!G26 -> 0.163
A30: Service revenues (marketplace commissions, fulfilment & brand-enablement fees) | C30: 868 | D30: 3397 | E30: 4740 | F30: =Interim!K16 -> 5637.0583 | G30: =G24*G29 -> 6363.9835 | H30: =H24*H29 -> 7043.9907 | I30: =I24*I29 -> 7777.0604 | J30: =J24*J29 -> 8539.2147 | K30: =K24*K29 -> 9189.2301
A31: YoY growth | D31: =IFERROR(D30/C30-1,0) -> 2.9135945 | E31: =IFERROR(E30/D30-1,0) -> 0.39534884 | F31: =IFERROR(F30/E30-1,0) -> 0.18925281 | G31: =IFERROR(G30/F30-1,0) -> 0.12895471 | H31: =IFERROR(H30/G30-1,0) -> 0.10685245 | I31: =IFERROR(I30/H30-1,0) -> 0.10407021 | J31: =IFERROR(J30/I30-1,0) -> 0.098000311 | K31: =IFERROR(K30/J30-1,0) -> 0.07612121
A32: Product revenues (first-party, own & partner brands) | C32: 31235 | D32: 35351 | E32: 37107 | F32: =Interim!K15 -> 36245.522 | G32: =G24-G30 -> 37525.558 | H32: =H24-H30 -> 39915.948 | I32: =I24-I30 -> 42397.523 | J32: =J24-J30 -> 44830.877 | K32: =K24-K30 -> 47186.414
A33: YoY growth | D33: =IFERROR(D32/C32-1,0) -> 0.13177525 | E33: =IFERROR(E32/D32-1,0) -> 0.049673277 | F33: =IFERROR(F32/E32-1,0) -> -0.023216059 | G33: =IFERROR(G32/F32-1,0) -> 0.035315711 | H33: =IFERROR(H32/G32-1,0) -> 0.063700305 | I33: =IFERROR(I32/H32-1,0) -> 0.062170016 | J33: =IFERROR(J32/I32-1,0) -> 0.057393791 | K33: =IFERROR(K32/J32-1,0) -> 0.052542743
A34: % of net revenues | C34: =IFERROR(C32/C24,0) -> 0.97296203 | D34: =IFERROR(D32/D24,0) -> 0.91233096 | E34: =IFERROR(E32/E24,0) -> 0.88673023 | F34: =IFERROR(F32/F24,0) -> 0.86540805 | G34: =IFERROR(G32/G24,0) -> 0.855 | H34: =IFERROR(H32/H24,0) -> 0.85 | I34: =IFERROR(I32/I24,0) -> 0.845 | J34: =IFERROR(J32/J24,0) -> 0.84 | K34: =IFERROR(K32/K24,0) -> 0.837
A35: Total net revenues | C35: =C32+C30 -> 32103 | D35: =D32+D30 -> 38748 | E35: =E32+E30 -> 41847 | F35: =F32+F30 -> 41882.58 | G35: =G32+G30 -> 43889.542 | H35: =H32+H30 -> 46959.938 | I35: =I32+I30 -> 50174.583 | J35: =J32+J30 -> 53370.092 | K35: =K32+K30 -> 56375.645
A36: Assumed blended marketplace take rate (analyst estimate) | C36: 0.25 | D36: 0.25 | E36: 0.25 | F36: 0.25 | G36: 0.25 | H36: 0.25 | I36: 0.25 | J36: 0.25 | K36: 0.25 | M36: Commission 10-20% of transaction value + fulfilment fees (Prospectus); not disclosed
A37: Memo: implied marketplace GMV (illustrative) | C37: =C30/C36 -> 3472 | D37: =D30/D36 -> 13588 | E37: =E30/E36 -> 18960 | F37: =F30/F36 -> 22548.233 | G37: =G30/G36 -> 25455.934 | H37: =H30/H36 -> 28175.963 | I37: =I30/I36 -> 31108.241 | J37: =J30/J36 -> 34156.859 | K37: =K30/K36 -> 36756.92
A38: Memo: implied gross sales (1P revenue + marketplace GMV) | C38: =C32+C37 -> 34707 | D38: =D32+D37 -> 48939 | E38: =E32+E37 -> 56067 | F38: =F32+F37 -> 58793.755 | G38: =G32+G37 -> 62981.492 | H38: =H32+H37 -> 68091.911 | I38: =I32+I37 -> 73505.764 | J38: =J32+J37 -> 78987.736 | K38: =K32+K37 -> 83943.335
A39: YoY growth | D39: =IFERROR(D38/C38-1,0) -> 0.41006137 | E39: =IFERROR(E38/D38-1,0) -> 0.14565071 | F39: =IFERROR(F38/E38-1,0) -> 0.048633865 | G39: =IFERROR(G38/F38-1,0) -> 0.071227587 | H39: =IFERROR(H38/G38-1,0) -> 0.081141589 | I39: =IFERROR(I38/H38-1,0) -> 0.079508029 | J39: =IFERROR(J38/I38-1,0) -> 0.074578803 | K39: =IFERROR(K38/J38-1,0) -> 0.062738837
A40: Net revenues by category (US$m)
A41: Apparel % of net revenues | C41: =IFERROR(C42/C24,0) -> 0.68778619 | D41: =IFERROR(D42/D24,0) -> 0.64694952 | E41: =IFERROR(E42/E24,0) -> 0.63820585 | F41: 0.615 | G41: 0.61 | H41: 0.605 | I41: 0.6 | J41: 0.595 | K41: 0.59 | M41: Category diversification (home, beauty, kids, sport); Q1'26 61.4%
...

Sheet Income Statement
A1: SHEIN Global Holdings Ltd (0625.HK) - Income Statement
A2: IFRS income statement (function of expense) with non-IFRS adjusted earnings. FY2026E = 1H26A + 2H26E.
A4: US$m unless stated | C4: FY2023A | D4: FY2024A | E4: FY2025A | F4: FY2026E | G4: FY2027E | H4: FY2028E | I4: FY2029E | J4: FY2030E | K4: FY2031E
A5: Net revenues (US$m)
A6: Net revenues | C6: ='Revenue Model'!C24 -> 32103 | D6: ='Revenue Model'!D24 -> 38748 | E6: ='Revenue Model'!E24 -> 41847 | F6: ='Revenue Model'!F24 -> 41882.58 | G6: ='Revenue Model'!G24 -> 43889.542 | H6: ='Revenue Model'!H24 -> 46959.938 | I6: ='Revenue Model'!I24 -> 50174.583 | J6: ='Revenue Model'!J24 -> 53370.092 | K6: ='Revenue Model'!K24 -> 56375.645
A7: YoY growth | D7: =IFERROR(D6/C6-1,0) -> 0.20699 | E7: =IFERROR(E6/D6-1,0) -> 0.079978321 | F7: =IFERROR(F6/E6-1,0) -> 0.00085024016 | G7: =IFERROR(G6/F6-1,0) -> 0.047918767 | H7: =IFERROR(H6/G6-1,0) -> 0.069957366 | I7: =IFERROR(I6/H6-1,0) -> 0.068455046 | J7: =IFERROR(J6/I6-1,0) -> 0.063687801 | K7: =IFERROR(K6/J6-1,0) -> 0.056315298
A8: Product revenues | C8: ='Revenue Model'!C32 -> 31235 | D8: ='Revenue Model'!D32 -> 35351 | E8: ='Revenue Model'!E32 -> 37107 | F8: ='Revenue Model'!F32 -> 36245.522 | G8: ='Revenue Model'!G32 -> 37525.558 | H8: ='Revenue Model'!H32 -> 39915.948 | I8: ='Revenue Model'!I32 -> 42397.523 | J8: ='Revenue Model'!J32 -> 44830.877 | K8: ='Revenue Model'!K32 -> 47186.414
A9: Service revenues | C9: ='Revenue Model'!C30 -> 868 | D9: ='Revenue Model'!D30 -> 3397 | E9: ='Revenue Model'!E30 -> 4740 | F9: ='Revenue Model'!F30 -> 5637.0583 | G9: ='Revenue Model'!G30 -> 6363.9835 | H9: ='Revenue Model'!H30 -> 7043.9907 | I9: ='Revenue Model'!I30 -> 7777.0604 | J9: ='Revenue Model'!J30 -> 8539.2147 | K9: ='Revenue Model'!K30 -> 9189.2301
A10: Operating expenses (US$m; shown as positive costs)
A11: Cost of sales | C11: 12777 | D11: 15249 | E11: 13433 | F11: =Interim!K26 -> 12422.257 | G11: =G8*G12 -> 12871.266 | H11: =H8*H12 -> 13651.254 | I11: =I8*I12 -> 14457.555 | J11: =J8*J12 -> 15242.498 | K11: =K8*K12 -> 16043.381
A12: % of product revenues | C12: =IFERROR(C11/C8,0) -> 0.40906035 | D12: =IFERROR(D11/D8,0) -> 0.43135979 | E12: =IFERROR(E11/E8,0) -> 0.36200717 | F12: =IFERROR(F11/F8,0) -> 0.3427253 | G12: =Scenarios!C31 -> 0.343 | H12: =Scenarios!D31 -> 0.342 | I12: =Scenarios!E31 -> 0.341 | J12: =Scenarios!F31 -> 0.34 | K12: =Scenarios!G31 -> 0.34
A13: % of net revenues | C13: =IFERROR(C11/C6,0) -> 0.39800019 | D13: =IFERROR(D11/D6,0) -> 0.39354289 | E13: =IFERROR(E11/E6,0) -> 0.3210027 | F13: =IFERROR(F11/F6,0) -> 0.29659723 | G13: =IFERROR(G11/G6,0) -> 0.293265 | H13: =IFERROR(H11/H6,0) -> 0.2907 | I13: =IFERROR(I11/I6,0) -> 0.288145 | J13: =IFERROR(J11/J6,0) -> 0.2856 | K13: =IFERROR(K11/K6,0) -> 0.28458
A14: Gross profit | C14: =C6-C11 -> 19326 | D14: =D6-D11 -> 23499 | E14: =E6-E11 -> 28414 | F14: =F6-F11 -> 29460.323 | G14: =G6-G11 -> 31018.275 | H14: =H6-H11 -> 33308.684 | I14: =I6-I11 -> 35717.028 | J14: =J6-J11 -> 38127.594 | K14: =K6-K11 -> 40332.264
A15: Gross margin | C15: =IFERROR(C14/C6,0) -> 0.60199981 | D15: =IFERROR(D14/D6,0) -> 0.60645711 | E15: =IFERROR(E14/E6,0) -> 0.6789973 | F15: =IFERROR(F14/F6,0) -> 0.70340277 | G15: =IFERROR(G14/G6,0) -> 0.706735 | H15: =IFERROR(H14/H6,0) -> 0.7093 | I15: =IFERROR(I14/I6,0) -> 0.711855 | J15: =IFERROR(J14/J6,0) -> 0.7144 | K15: =IFERROR(K14/K6,0) -> 0.71542
A16: Fulfilment expenses (logistics, warehousing, duties on direct shipments) | C16: 13501 | D16: 16847 | E16: 19072 | F16: =Interim!K30 -> 21000.776 | G16: =G6*G17 -> 22164.219 | H16: =H6*H17 -> 23573.889 | I16: =I6*I17 -> 25087.292 | J16: =J6*J17 -> 26685.046 | K16: =K6*K17 -> 28187.822
A17: % of net revenues | C17: =IFERROR(C16/C6,0) -> 0.4205526 | D17: =IFERROR(D16/D6,0) -> 0.43478373 | E17: =IFERROR(E16/E6,0) -> 0.45575549 | F17: =IFERROR(F16/F6,0) -> 0.5014203 | G17: =Scenarios!C36 -> 0.505 | H17: =Scenarios!D36 -> 0.502 | I17: =Scenarios!E36 -> 0.5 | J17: =Scenarios!F36 -> 0.5 | K17: =Scenarios!G36 -> 0.5
A18: per order (US$) | C18: =C16/'Revenue Model'!C9 -> 18.882517 | D18: =D16/'Revenue Model'!D9 -> 18.331882 | E18: =E16/'Revenue Model'!E9 -> 17.692022 | F18: =F16/'Revenue Model'!F9 -> 18.362779 | G18: =G16/'Revenue Model'!G9 -> 18.103585 | H18: =H16/'Revenue Model'!H9 -> 18.102986 | I18: =I16/'Revenue Model'!I9 -> 18.289714 | J18: =J16/'Revenue Model'!J9 -> 18.472466 | K18: =K16/'Revenue Model'!K9 -> 18.852897
A19: Contribution after fulfilment | C19: =C14-C16 -> 5825 | D19: =D14-D16 -> 6652 | E19: =E14-E16 -> 9342 | F19: =F14-F16 -> 8459.5468 | G19: =G14-G16 -> 8854.0567 | H19: =H14-H16 -> 9734.7952 | I19: =I14-I16 -> 10629.736 | J19: =J14-J16 -> 11442.548 | K19: =K14-K16 -> 12144.441
A20: Contribution margin | C20: =IFERROR(C19/C6,0) -> 0.18144722 | D20: =IFERROR(D19/D6,0) -> 0.17167338 | E20: =IFERROR(E19/E6,0) -> 0.22324181 | F20: =IFERROR(F19/F6,0) -> 0.20198247 | G20: =IFERROR(G19/G6,0) -> 0.201735 | H20: =IFERROR(H19/H6,0) -> 0.2073 | I20: =IFERROR(I19/I6,0) -> 0.211855 | J20: =IFERROR(J19/J6,0) -> 0.2144 | K20: =IFERROR(K19/K6,0) -> 0.21542
A21: Marketing expenses | C21: 3453 | D21: 4159 | E21: 6191 | F21: =Interim!K33 -> 5877.0583 | G21: =G6*G22 -> 5925.0881 | H21: =H6*H22 -> 6245.6718 | I21: =I6*I22 -> 6623.045 | J21: =J6*J22 -> 7044.8521 | K21: =K6*K22 -> 7441.5851
A22: % of net revenues | C22: =IFERROR(C21/C6,0) -> 0.10756004 | D22: =IFERROR(D21/D6,0) -> 0.10733457 | E22: =IFERROR(E21/E6,0) -> 0.1479437 | F22: =IFERROR(F21/F6,0) -> 0.14032226 | G22: =Scenarios!C41 -> 0.135 | H22: =Scenarios!D41 -> 0.133 | I22: =Scenarios!E41 -> 0.132 | J22: =Scenarios!F41 -> 0.132 | K22: =Scenarios!G41 -> 0.132
A23: Technology & content expenses | C23: 668 | D23: 849 | E23: 896 | F23: =Interim!K35 -> 999.21734 | G23: =G6*G24 -> 1053.349 | H23: =H6*H24 -> 1127.0385 | I23: =I6*I24 -> 1204.19 | J23: =J6*J24 -> 1280.8822 | K23: =K6*K24 -> 1353.0155
A24: % of net revenues | C24: =IFERROR(C23/C6,0) -> 0.020808024 | D24: =IFERROR(D23/D6,0) -> 0.021910808 | E24: =IFERROR(E23/E6,0) -> 0.021411332 | F24: =IFERROR(F23/F6,0) -> 0.023857588 | G24: =Scenarios!C46 -> 0.024 | H24: =Scenarios!D46 -> 0.024 | I24: =Scenarios!E46 -> 0.024 | J24: =Scenarios!F46 -> 0.024 | K24: =Scenarios!G46 -> 0.024
A25: General & administrative expenses | C25: 328 | D25: 678 | E25: 548 | F25: =Interim!K37 -> 548.73154 | G25: =G6*G26 -> 570.56404 | H25: =H6*H26 -> 610.4792 | I25: =I6*I26 -> 652.26958 | J25: =J6*J26 -> 693.81119 | K25: =K6*K26 -> 732.88338
A26: % of net revenues | C26: =IFERROR(C25/C6,0) -> 0.010217114 | D26: =IFERROR(D25/D6,0) -> 0.017497677 | E26: =IFERROR(E25/E6,0) -> 0.013095323 | F26: =IFERROR(F25/F6,0) -> 0.013101665 | G26: =Scenarios!C51 -> 0.013 | H26: =Scenarios!D51 -> 0.013 | I26: =Scenarios!E51 -> 0.013 | J26: =Scenarios!F51 -> 0.013 | K26: =Scenarios!G51 -> 0.013
A27: Total operating expenses | C27: =C11+C16+C21+C23+C25 -> 30727 | D27: =D11+D16+D21+D23+D25 -> 37782 | E27: =E11+E16+E21+E23+E25 -> 40140 | F27: =F11+F16+F21+F23+F25 -> 40848.04 | G27: =G11+G16+G21+G23+G25 -> 42584.486 | H27: =H11+H16+H21+H23+H25 -> 45208.333 | I27: =I11+I16+I21+I23+I25 -> 48024.351 | J27: =J11+J16+J21+J23+J25 -> 50947.09 | K27: =K11+K16+K21+K23+K25 -> 53758.687
A28: % of net revenues | C28: =IFERROR(C27/C6,0) -> 0.95713796 | D28: =IFERROR(D27/D6,0) -> 0.97506968 | E28: =IFERROR(E27/E6,0) -> 0.95920855 | F28: =IFERROR(F27/F6,0) -> 0.97529905 | G28: =IFERROR(G27/G6,0) -> 0.970265 | H28: =IFERROR(H27/H6,0) -> 0.9627 | I28: =IFERROR(I27/I6,0) -> 0.957145 | J28: =IFERROR(J27/J6,0) -> 0.9546 | K28: =IFERROR(K27/K6,0) -> 0.95358
A29: Operating income (EBIT, IFRS) | C29: =C6-C27 -> 1376 | D29: =D6-D27 -> 966 | E29: =E6-E27 -> 1707 | F29: =F6-F27 -> 1034.5396 | G29: =G6-G27 -> 1305.0555 | H29: =H6-H27 -> 1751.6057 | I29: =I6-I27 -> 2150.2318 | J29: =J6-J27 -> 2423.0022 | K29: =K6-K27 -> 2616.9574
A30: Operating margin | C30: =IFERROR(C29/C6,0) -> 0.042862038 | D30: =IFERROR(D29/D6,0) -> 0.024930319 | E30: =IFERROR(E29/E6,0) -> 0.040791455 | F30: =IFERROR(F29/F6,0) -> 0.024700953 | G30: =IFERROR(G29/G6,0) -> 0.029735 | H30: =IFERROR(H29/H6,0) -> 0.0373 | I30: =IFERROR(I29/I6,0) -> 0.042855 | J30: =IFERROR(J29/J6,0) -> 0.0454 | K30: =IFERROR(K29/K6,0) -> 0.04642
A31: YoY growth | D31: =IFERROR(D29/C29-1,0) -> -0.29796512 | E31: =IFERROR(E29/D29-1,0) -> 0.76708075 | F31: =IFERROR(F29/E29-1,0) -> -0.3939428 | G31: =IFERROR(G29/F29-1,0) -> 0.2614843 | H31: =IFERROR(H29/G29-1,0) -> 0.34216949 | I31: =IFERROR(I29/H29-1,0) -> 0.22757751 | J31: =IFERROR(J29/I29-1,0) -> 0.12685629 | K31: =IFERROR(K29/J29-1,0) -> 0.080047492
A32: Share-based compensation (included above) | C32: 49 | D32: 71 | E32: 85 | F32: =Interim!K41 -> 90 | G32: 100 | H32: 105 | I32: 110 | J32: 115 | K32: 120 | M32: Post-IPO share scheme grants
A33: Adjusted EBIT (non-IFRS) | C33: =C29+C32 -> 1425 | D33: =D29+D32 -> 1037 | E33: =E29+E32 -> 1792 | F33: =F29+F32 -> 1124.5396 | G33: =G29+G32 -> 1405.0555 | H33: =H29+H32 -> 1856.6057 | I33: =I29+I32 -> 2260.2318 | J33: =J29+J32 -> 2538.0022 | K33: =K29+K32 -> 2736.9574
A34: Adjusted EBIT margin | C34: =IFERROR(C33/C6,0) -> 0.044388375 | D34: =IFERROR(D33/D6,0) -> 0.026762672 | E34: =IFERROR(E33/E6,0) -> 0.042822664 | F34: =IFERROR(F33/F6,0) -> 0.026849818 | G34: =IFERROR(G33/G6,0) -> 0.032013447 | H34: =IFERROR(H33/H6,0) -> 0.039535948 | I34: =IFERROR(I33/I6,0) -> 0.045047345 | J34: =IFERROR(J33/J6,0) -> 0.047554765 | K34: =IFERROR(K33/K6,0) -> 0.048548579
A35: D&A of PP&E and intangibles, % of revenues | C35: =IFERROR(C36/C6,0) -> 0.0018066847 | D35: =IFERROR(D36/D6,0) -> 0.0032001652 | E35: =IFERROR(E36/E6,0) -> 0.0036083829 | F35: 0.0043 | G35: 0.0043 | H35: 0.0043 | I35: 0.0043 | J35: 0.0043 | K35: 0.0043
A36: D&A of property, equipment & intangibles | C36: 58 | D36: 124 | E36: 151 | F36: =F6*F35 -> 180.09509 | G36: =G6*G35 -> 188.72503 | H36: =H6*H35 -> 201.92773 | I36: =I6*I35 -> 215.75071 | J36: =J6*J35 -> 229.4914 | K36: =K6*K35 -> 242.41527
A37: Right-of-use depreciation, % of revenues | C37: =IFERROR(C38/C6,0) -> 0.0037068187 | D37: =IFERROR(D38/D6,0) -> 0.0051615567 | E37: =IFERROR(E38/E6,0) -> 0.0059024542 | F37: 0.0068 | G37: 0.0068 | H37: 0.0068 | I37: 0.0068 | J37: 0.0068 | K37: 0.0068
A38: Depreciation of right-of-use assets (warehouse & office leases) | C38: 119 | D38: 200 | E38: 247 | F38: =F6*F37 -> 284.80154 | G38: =G6*G37 -> 298.44888 | H38: =H6*H37 -> 319.32758 | I38: =I6*I37 -> 341.18716 | J38: =J6*J37 -> 362.91662 | K38: =K6*K37 -> 383.35438
A39: EBITDA (IFRS 16) | C39: =C29+C36+C38 -> 1553 | D39: =D29+D36+D38 -> 1290 | E39: =E29+E36+E38 -> 2105 | F39: =F29+F36+F38 -> 1499.4363 | G39: =G29+G36+G38 -> 1792.2294 | H39: =H29+H36+H38 -> 2272.861 | I39: =I29+I36+I38 -> 2707.1696 | J39: =J29+J36+J38 -> 3015.4102 | K39: =K29+K36+K38 -> 3242.7271
A40: EBITDA margin | C40: =IFERROR(C39/C6,0) -> 0.048375541 | D40: =IFERROR(D39/D6,0) -> 0.033292041 | E40: =IFERROR(E39/E6,0) -> 0.050302292 | F40: =IFERROR(F39/F6,0) -> 0.035800953 | G40: =IFERROR(G39/G6,0) -> 0.040835 | H40: =IFERROR(H39/H6,0) -> 0.0484 | I40: =IFERROR(I39/I6,0) -> 0.053955 | J40: =IFERROR(J39/J6,0) -> 0.0565 | K40: =IFERROR(K39/K6,0) -> 0.05752
A41: Adjusted EBITDA (ex SBC) | C41: =C39+C32 -> 1602 | D41: =D39+D32 -> 1361 | E41: =E39+E32 -> 2190 | F41: =F39+F32 -> 1589.4363 | G41: =G39+G32 -> 1892.2294 | H41: =H39+H32 -> 2377.861 | I41: =I39+I32 -> 2817.1696 | J41: =J39+J32 -> 3130.4102 | K41: =K39+K32 -> 3362.7271
...

Sheet Balance Sheet
A1: SHEIN Global Holdings Ltd (0625.HK) - Balance Sheet
A2: Consolidated balance sheet; FY2026E reflects preferred-share conversion, IPO proceeds and listing payments.
A4: US$m unless stated | C4: FY2023A | D4: FY2024A | E4: FY2025A | F4: FY2026E | G4: FY2027E | H4: FY2028E | I4: FY2029E | J4: FY2030E | K4: FY2031E
A5: Assets (US$m)
A6: Cash and cash equivalents | C6: 3494 | D6: 2905 | E6: 4481 | F6: ='Cash Flow'!F45 -> 1710.8837 | G6: ='Cash Flow'!G45 -> 2703.9375 | H6: ='Cash Flow'!H45 -> 3986.3814 | I6: ='Cash Flow'!I45 -> 5434.8656 | J6: ='Cash Flow'!J45 -> 6964.1978 | K6: ='Cash Flow'!K45 -> 8527.8587
A7: Restricted cash | C7: 437 | D7: 485 | E7: 550 | F7: =Interim!I64 -> 622 | G7: =F7 -> 622 | H7: =G7 -> 622 | I7: =H7 -> 622 | J7: =I7 -> 622 | K7: =J7 -> 622
A8: Short-term investments (time deposits) | C8: 6265 | D8: 8086 | E8: 9723 | F8: =Interim!I66 -> 11545 | G8: =F8 -> 11545 | H8: =G8 -> 11545 | I8: =H8 -> 11545 | J8: =I8 -> 11545 | K8: =J8 -> 11545
A9: Receivables from payment platforms & service providers | C9: 823 | D9: 1303 | E9: 718 | F9: =F62/365*'Income Statement'!F6 -> 803.22756 | G9: =G62/365*'Income Statement'!G6 -> 841.71724 | H9: =H62/365*'Income Statement'!H6 -> 900.60156 | I9: =I62/365*'Income Statement'!I6 -> 962.25228 | J9: =J62/365*'Income Statement'!J6 -> 1023.536 | K9: =K62/365*'Income Statement'!K6 -> 1081.1767
A10: Other receivables and prepayments | C10: 273 | D10: 480 | E10: 534 | F10: =F63*'Income Statement'!F6 -> 544.47354 | G10: =G63*'Income Statement'!G6 -> 570.56404 | H10: =H63*'Income Statement'!H6 -> 610.4792 | I10: =I63*'Income Statement'!I6 -> 652.26958 | J10: =J63*'Income Statement'!J6 -> 693.81119 | K10: =K63*'Income Statement'!K6 -> 732.88338
A11: Inventories | C11: 1637 | D11: 1500 | E11: 1261 | F11: =F64/365*'Income Statement'!F11 -> 1191.1754 | G11: =G64/365*'Income Statement'!G11 -> 1234.231 | H11: =H64/365*'Income Statement'!H11 -> 1309.0244 | I11: =I64/365*'Income Statement'!I11 -> 1386.3409 | J11: =J64/365*'Income Statement'!J11 -> 1461.6094 | K11: =K64/365*'Income Statement'!K11 -> 1538.4064
A12: Other current assets | C12: 88 | D12: 127 | E12: 326 | F12: =F65*'Income Statement'!F6 -> 335.06064 | G12: =G65*'Income Statement'!G6 -> 351.11633 | H12: =H65*'Income Statement'!H6 -> 375.67951 | I12: =I65*'Income Statement'!I6 -> 401.39666 | J12: =J65*'Income Statement'!J6 -> 426.96074 | K12: =K65*'Income Statement'!K6 -> 451.00516
A13: Total current assets | C13: =SUM(C6:C12) -> 13017 | D13: =SUM(D6:D12) -> 14886 | E13: =SUM(E6:E12) -> 17593 | F13: =SUM(F6:F12) -> 16751.821 | G13: =SUM(G6:G12) -> 17868.566 | H13: =SUM(H6:H12) -> 19349.166 | I13: =SUM(I6:I12) -> 21004.125 | J13: =SUM(J6:J12) -> 22737.115 | K13: =SUM(K6:K12) -> 24498.33
A14: Property and equipment | C14: 396 | D14: 551 | E14: 619 | F14: =E14-'Cash Flow'!F27-'Income Statement'!F36 -> 732.08297 | G14: =F14-'Cash Flow'!G27-'Income Statement'!G36 -> 872.5295 | H14: =G14-'Cash Flow'!H27-'Income Statement'!H36 -> 1022.8013 | I14: =H14-'Cash Flow'!I27-'Income Statement'!I36 -> 1183.36 | J14: =I14-'Cash Flow'!J27-'Income Statement'!J36 -> 1354.1443 | K14: =J14-'Cash Flow'!K27-'Income Statement'!K36 -> 1534.5463
A15: Right-of-use assets | C15: 497 | D15: 959 | E15: 1105 | F15: =F70*'Income Statement'!F6 -> 1130.8297 | G15: =G70*'Income Statement'!G6 -> 1185.0176 | H15: =H70*'Income Statement'!H6 -> 1267.9183 | I15: =I70*'Income Statement'!I6 -> 1354.7137 | J15: =J70*'Income Statement'!J6 -> 1440.9925 | K15: =K70*'Income Statement'!K6 -> 1522.1424
A16: Intangible assets & goodwill | C16: 40 | D16: 39 | E16: 38 | F16: =Interim!I71 -> 135 | G16: =F16 -> 135 | H16: =G16 -> 135 | I16: =H16 -> 135 | J16: =I16 -> 135 | K16: =J16 -> 135
A17: Non-current restricted cash | C17: 78 | D17: 34 | E17: 32 | F17: =Interim!I65 -> 38 | G17: =F17 -> 38 | H17: =G17 -> 38 | I17: =H17 -> 38 | J17: =I17 -> 38 | K17: =J17 -> 38
A18: Deferred tax assets | C18: 81 | D18: 94 | E18: 102 | F18: =Interim!I72 -> 125 | G18: =F18 -> 125 | H18: =G18 -> 125 | I18: =H18 -> 125 | J18: =I18 -> 125 | K18: =J18 -> 125
A19: Investments in associates | C19: 470 | D19: 251 | E19: 266 | F19: =E19+'Income Statement'!F45 -> 251 | G19: =F19+'Income Statement'!G45 -> 251 | H19: =G19+'Income Statement'!H45 -> 251 | I19: =H19+'Income Statement'!I45 -> 251 | J19: =I19+'Income Statement'!J45 -> 251 | K19: =J19+'Income Statement'!K45 -> 251
A20: Investments at fair value through profit or loss | C20: 82 | D20: 169 | E20: 158 | F20: =Interim!I74 -> 162 | G20: =F20 -> 162 | H20: =G20 -> 162 | I20: =H20 -> 162 | J20: =I20 -> 162 | K20: =J20 -> 162
A21: Long-term time deposits | C21: 0 | D21: 211 | E21: 0 | F21: =E21 -> 0 | G21: =F21 -> 0 | H21: =G21 -> 0 | I21: =H21 -> 0 | J21: =I21 -> 0 | K21: =J21 -> 0
A22: Other non-current assets | C22: 157 | D22: 127 | E22: 120 | F22: =Interim!I75 -> 109 | G22: =F22 -> 109 | H22: =G22 -> 109 | I22: =H22 -> 109 | J22: =I22 -> 109 | K22: =J22 -> 109
A23: Total non-current assets | C23: =SUM(C14:C22) -> 1801 | D23: =SUM(D14:D22) -> 2435 | E23: =SUM(E14:E22) -> 2440 | F23: =SUM(F14:F22) -> 2682.9126 | G23: =SUM(G14:G22) -> 2877.5471 | H23: =SUM(H14:H22) -> 3110.7196 | I23: =SUM(I14:I22) -> 3358.0737 | J23: =SUM(J14:J22) -> 3615.1367 | K23: =SUM(K14:K22) -> 3876.6887
A24: Total assets | C24: =C13+C23 -> 14818 | D24: =D13+D23 -> 17321 | E24: =E13+E23 -> 20033 | F24: =F13+F23 -> 19434.733 | G24: =G13+G23 -> 20746.113 | H24: =H13+H23 -> 22459.886 | I24: =I13+I23 -> 24362.199 | J24: =J13+J23 -> 26352.252 | K24: =K13+K23 -> 28375.019
A25: Liabilities (US$m)
A26: Accounts payable | C26: 2749 | D26: 2935 | E26: 3019 | F26: =F66/365*('Income Statement'!F11+'Income Statement'!F16) -> 3113.3784 | G26: =G66/365*('Income Statement'!G11+'Income Statement'!G16) -> 3263.5794 | H26: =H66/365*('Income Statement'!H11+'Income Statement'!H16) -> 3467.5476 | I26: =I66/365*('Income Statement'!I11+'Income Statement'!I16) -> 3683.6296 | J26: =J66/365*('Income Statement'!J11+'Income Statement'!J16) -> 3905.5795 | K26: =K66/365*('Income Statement'!K11+'Income Statement'!K16) -> 4120.1669
A27: Accrued expenses & other current liabilities (ex lease) | C27: 1836 | D27: 2623 | E27: 3035 | F27: =F67*'Income Statement'!F6 -> 3057.4283 | G27: =G67*'Income Statement'!G6 -> 3203.9365 | H27: =H67*'Income Statement'!H6 -> 3428.0755 | I27: =I67*'Income Statement'!I6 -> 3662.7446 | J27: =J67*'Income Statement'!J6 -> 3896.0167 | K27: =K67*'Income Statement'!K6 -> 4115.422 | M27: Reported line less current lease liabilities
A28: Lease liabilities - current | C28: 122 | D28: 191 | E28: 233 | F28: =F55*F71 -> 236.63423 | G28: =G55*G71 -> 248.0137 | H28: =H55*H71 -> 265.42285 | I28: =I55*I71 -> 283.64989 | J28: =J55*J71 -> 301.76842 | K28: =K55*K71 -> 318.8099
A29: Contract liabilities (customer prepayments) | C29: 694 | D29: 770 | E29: 789 | F29: =F68*'Income Statement'!F6 -> 795.76902 | G29: =G68*'Income Statement'!G6 -> 833.90129 | H29: =H68*'Income Statement'!H6 -> 892.23883 | I29: =I68*'Income Statement'!I6 -> 953.31708 | J29: =J68*'Income Statement'!J6 -> 1014.0317 | K29: =K68*'Income Statement'!K6 -> 1071.1372
A30: Income tax payable | C30: 707 | D30: 771 | E30: 933 | F30: =F69*'Income Statement'!F6 -> 837.6516 | G30: =G69*'Income Statement'!G6 -> 877.79083 | H30: =H69*'Income Statement'!H6 -> 939.19877 | I30: =I69*'Income Statement'!I6 -> 1003.4917 | J30: =J69*'Income Statement'!J6 -> 1067.4018 | K30: =K69*'Income Statement'!K6 -> 1127.5129
A31: Convertible redeemable preferred shares - current | C31: 0 | D31: 0 | E31: 18048 | F31: 0 | G31: 0 | H31: 0 | I31: 0 | J31: 0 | K31: 0
A32: Total current liabilities | C32: =SUM(C26:C31) -> 6108 | D32: =SUM(D26:D31) -> 7290 | E32: =SUM(E26:E31) -> 26057 | F32: =SUM(F26:F31) -> 8040.8616 | G32: =SUM(G26:G31) -> 8427.2218 | H32: =SUM(H26:H31) -> 8992.4835 | I32: =SUM(I26:I31) -> 9586.8327 | J32: =SUM(J26:J31) -> 10184.798 | K32: =SUM(K26:K31) -> 10753.049
A33: Convertible redeemable preferred shares - non-current | C33: 20807 | D33: 18376 | E33: 0 | F33: 0 | G33: 0 | H33: 0 | I33: 0 | J33: 0 | K33: 0
A34: Deferred tax liabilities | C34: 1 | D34: 7 | E34: 5 | F34: =Interim!I84 -> 15 | G34: =F34 -> 15 | H34: =G34 -> 15 | I34: =H34 -> 15 | J34: =I34 -> 15 | K34: =J34 -> 15
A35: Lease liabilities - non-current | C35: 407 | D35: 744 | E35: 868 | F35: =F55-F28 -> 890.19543 | G35: =G55-G28 -> 933.00392 | H35: =H55-H28 -> 998.49548 | I35: =I55-I28 -> 1067.0639 | J35: =J55-J28 -> 1135.2241 | K35: =K55-K28 -> 1199.3325
A36: Other long-term liabilities | C36: 6 | D36: 1 | E36: 0 | F36: =Interim!I85 -> 31 | G36: =F36 -> 31 | H36: =G36 -> 31 | I36: =H36 -> 31 | J36: =I36 -> 31 | K36: =J36 -> 31
A37: Total non-current liabilities | C37: =SUM(C33:C36) -> 21221 | D37: =SUM(D33:D36) -> 19128 | E37: =SUM(E33:E36) -> 873 | F37: =SUM(F33:F36) -> 936.19543 | G37: =SUM(G33:G36) -> 979.00392 | H37: =SUM(H33:H36) -> 1044.4955 | I37: =SUM(I33:I36) -> 1113.0639 | J37: =SUM(J33:J36) -> 1181.2241 | K37: =SUM(K33:K36) -> 1245.3325
A38: Total liabilities | C38: =C32+C37 -> 27329 | D38: =D32+D37 -> 26418 | E38: =E32+E37 -> 26930 | F38: =F32+F37 -> 8977.0571 | G38: =G32+G37 -> 9406.2257 | H38: =H32+H37 -> 10036.979 | I38: =I32+I37 -> 10699.897 | J38: =J32+J37 -> 11366.022 | K38: =K32+K37 -> 11998.381
A39: Shareholders' equity (US$m)
A40: Total shareholders' equity / (deficit) | C40: -12511 | D40: -9097 | E40: -6897 | F40: =F53 -> 10457.676 | G40: =G53 -> 11339.888 | H40: =H53 -> 12422.907 | I40: =I53 -> 13662.302 | J40: =J53 -> 14986.23 | K40: =K53 -> 16376.638
A41: Total liabilities & shareholders' equity | C41: =C38+C40 -> 14818 | D41: =D38+D40 -> 17321 | E41: =E38+E40 -> 20033 | F41: =F38+F40 -> 19434.733 | G41: =G38+G40 -> 20746.113 | H41: =H38+H40 -> 22459.886 | I41: =I38+I40 -> 24362.199 | J41: =J38+J40 -> 26352.252 | K41: =K38+K40 -> 28375.019
...

Sheet Cash Flow
A1: SHEIN Global Holdings Ltd (0625.HK) - Cash Flow
A2: Cash-flow statement (company presentation). Projections derived from balance-sheet movements.
A4: US$m unless stated | C4: FY2023A | D4: FY2024A | E4: FY2025A | F4: FY2026E | G4: FY2027E | H4: FY2028E | I4: FY2029E | J4: FY2030E | K4: FY2031E
A5: Operating activities (US$m; company presentation - interest received shown in investing)
A6: Income before income taxes | C6: 2995 | D6: 3769 | E6: 2514 | F6: ='Income Statement'!F51 -> 7267.6832 | G6: ='Income Statement'!G51 -> 1740.193 | H6: ='Income Statement'!H51 -> 2188.0697 | I6: ='Income Statement'!I51 -> 2609.2855 | J6: ='Income Statement'!J51 -> 2925.0626 | K6: ='Income Statement'!K51 -> 3164.9775
A7: Inventory write-downs, credit losses, impairments & other | C7: 120 | D7: 157 | E7: 181 | F7: 0 | G7: 0 | H7: 0 | I7: 0 | J7: 0 | K7: 0
A8: Depreciation of right-of-use assets | C8: 119 | D8: 200 | E8: 247 | F8: ='Income Statement'!F38 -> 284.80154 | G8: ='Income Statement'!G38 -> 298.44888 | H8: ='Income Statement'!H38 -> 319.32758 | I8: ='Income Statement'!I38 -> 341.18716 | J8: ='Income Statement'!J38 -> 362.91662 | K8: ='Income Statement'!K38 -> 383.35438
A9: D&A of property, equipment & intangibles | C9: 58 | D9: 124 | E9: 151 | F9: ='Income Statement'!F36 -> 180.09509 | G9: ='Income Statement'!G36 -> 188.72503 | H9: ='Income Statement'!H36 -> 201.92773 | I9: ='Income Statement'!I36 -> 215.75071 | J9: ='Income Statement'!J36 -> 229.4914 | K9: ='Income Statement'!K36 -> 242.41527
A10: Interest expense on lease liabilities | C10: 25 | D10: 44 | E10: 56 | F10: 0 | G10: 0 | H10: 0 | I10: 0 | J10: 0 | K10: 0 | M10: Projections: lease cost treated as operating
A11: Interest income (reclassified to investing) | C11: -472 | D11: -597 | E11: -621 | F11: =-'Income Statement'!F47 -> -584.83526 | G11: =-'Income Statement'!G47 -> -500.97181 | H11: =-'Income Statement'!H47 -> -506.90388 | I11: =-'Income Statement'!I47 -> -534.31559 | J11: =-'Income Statement'!J47 -> -582.11557 | K11: =-'Income Statement'!K47 -> -632.58353
A12: Share of (income)/losses from associates | C12: 36 | D12: 171 | E12: -3 | F12: =-'Income Statement'!F45 -> 15 | G12: =-'Income Statement'!G45 -> 0 | H12: =-'Income Statement'!H45 -> 0 | I12: =-'Income Statement'!I45 -> 0 | J12: =-'Income Statement'!J45 -> 0 | K12: =-'Income Statement'!K45 -> 0
A13: Share-based compensation | C13: 49 | D13: 71 | E13: 85 | F13: ='Income Statement'!F32 -> 90 | G13: ='Income Statement'!G32 -> 100 | H13: ='Income Statement'!H32 -> 105 | I13: ='Income Statement'!I32 -> 110 | J13: ='Income Statement'!J32 -> 115 | K13: ='Income Statement'!K32 -> 120
A14: FV changes of convertible redeemable preferred shares | C14: -1231 | D14: -2431 | E14: -328 | F14: =-'Income Statement'!F44 -> -5884.3083 | G14: =-'Income Statement'!G44 -> 0 | H14: =-'Income Statement'!H44 -> 0 | I14: =-'Income Statement'!I44 -> 0 | J14: =-'Income Statement'!J44 -> 0 | K14: =-'Income Statement'!K44 -> 0
A15: Change in receivables from payment platforms | C15: -309 | D15: -542 | E15: 647 | F15: =-('Balance Sheet'!F9-'Balance Sheet'!E9) -> -85.227562 | G15: =-('Balance Sheet'!G9-'Balance Sheet'!F9) -> -38.489675 | H15: =-('Balance Sheet'!H9-'Balance Sheet'!G9) -> -58.88432 | I15: =-('Balance Sheet'!I9-'Balance Sheet'!H9) -> -61.650721 | J15: =-('Balance Sheet'!J9-'Balance Sheet'!I9) -> -61.283732 | K15: =-('Balance Sheet'!K9-'Balance Sheet'!J9) -> -57.640735
A16: Change in other receivables, prepayments & other assets | C16: -163 | D16: -286 | E16: -204 | F16: =-(('Balance Sheet'!F10-'Balance Sheet'!E10)+('Balance Sheet'!F12-'Balance Sheet'!E12)+('Balance Sheet'!F22-'Balance Sheet'!E22)+('Balance Sheet'!F18-'Balance Sheet'!E18)) -> -31.53418 | G16: =-(('Balance Sheet'!G10-'Balance Sheet'!F10)+('Balance Sheet'!G12-'Balance Sheet'!F12)+('Balance Sheet'!G22-'Balance Sheet'!F22)+('Balance Sheet'!G18-'Balance Sheet'!F18)) -> -42.146194 | H16: =-(('Balance Sheet'!H10-'Balance Sheet'!G10)+('Balance Sheet'!H12-'Balance Sheet'!G12)+('Balance Sheet'!H22-'Balance Sheet'!G22)+('Balance Sheet'!H18-'Balance Sheet'!G18)) -> -64.478331 | I16: =-(('Balance Sheet'!I10-'Balance Sheet'!H10)+('Balance Sheet'!I12-'Balance Sheet'!H12)+('Balance Sheet'!I22-'Balance Sheet'!H22)+('Balance Sheet'!I18-'Balance Sheet'!H18)) -> -67.507539 | J16: =-(('Balance Sheet'!J10-'Balance Sheet'!I10)+('Balance Sheet'!J12-'Balance Sheet'!I12)+('Balance Sheet'!J22-'Balance Sheet'!I22)+('Balance Sheet'!J18-'Balance Sheet'!I18)) -> -67.105686 | K16: =-(('Balance Sheet'!K10-'Balance Sheet'!J10)+('Balance Sheet'!K12-'Balance Sheet'!J12)+('Balance Sheet'!K22-'Balance Sheet'!J22)+('Balance Sheet'!K18-'Balance Sheet'!J18)) -> -63.116605
A17: Change in inventories | C17: -862 | D17: -83 | E17: 74 | F17: =-('Balance Sheet'!F11-'Balance Sheet'!E11) -> 69.824635 | G17: =-('Balance Sheet'!G11-'Balance Sheet'!F11) -> -43.055661 | H17: =-('Balance Sheet'!H11-'Balance Sheet'!G11) -> -74.793336 | I17: =-('Balance Sheet'!I11-'Balance Sheet'!H11) -> -77.31655 | J17: =-('Balance Sheet'!J11-'Balance Sheet'!I11) -> -75.268509 | K17: =-('Balance Sheet'!K11-'Balance Sheet'!J11) -> -76.796969
A18: Change in accounts payable | C18: 927 | D18: 228 | E18: 36 | F18: =('Balance Sheet'!F26-'Balance Sheet'!E26) -> 94.378433 | G18: =('Balance Sheet'!G26-'Balance Sheet'!F26) -> 150.20098 | H18: =('Balance Sheet'!H26-'Balance Sheet'!G26) -> 203.96816 | I18: =('Balance Sheet'!I26-'Balance Sheet'!H26) -> 216.08198 | J18: =('Balance Sheet'!J26-'Balance Sheet'!I26) -> 221.9499 | K18: =('Balance Sheet'!K26-'Balance Sheet'!J26) -> 214.58741
A19: Change in contract liabilities | C19: 99 | D19: 99 | E19: -27 | F19: =('Balance Sheet'!F29-'Balance Sheet'!E29) -> 6.76902 | G19: =('Balance Sheet'!G29-'Balance Sheet'!F29) -> 38.13227 | H19: =('Balance Sheet'!H29-'Balance Sheet'!G29) -> 58.337537 | I19: =('Balance Sheet'!I29-'Balance Sheet'!H29) -> 61.07825 | J19: =('Balance Sheet'!J29-'Balance Sheet'!I29) -> 60.714669 | K19: =('Balance Sheet'!K29-'Balance Sheet'!J29) -> 57.1055
A20: Change in accrued expenses & other current liabilities | C20: 725 | D20: 854 | E20: 334 | F20: =('Balance Sheet'!F27-'Balance Sheet'!E27) -> 22.42834 | G20: =('Balance Sheet'!G27-'Balance Sheet'!F27) -> 146.5082 | H20: =('Balance Sheet'!H27-'Balance Sheet'!G27) -> 224.13896 | I20: =('Balance Sheet'!I27-'Balance Sheet'!H27) -> 234.66906 | J20: =('Balance Sheet'!J27-'Balance Sheet'!I27) -> 233.27215 | K20: =('Balance Sheet'!K27-'Balance Sheet'!J27) -> 219.40534
